{levelname} {asctime} {module} {process:d} {thread:d} {message}
{levelname} {asctime} {module} {process:d} {thread:d} {message}
{levelname} {asctime} {module} {process:d} {thread:d} {message}
{levelname} {asctime} {module} {process:d} {thread:d} {message}
{levelname} {asctime} {module} {process:d} {thread:d} {message}
Traceback (most recent call last):
  File "/home/gaoi/.virtualenvs/mytaste/lib/python3.6/site-packages/django/contrib/sessions/backends/base.py", line 199, in _get_session
    return self._session_cache
AttributeError: 'SessionStore' object has no attribute '_session_cache'

During handling of the above exception, another exception occurred:

Traceback (most recent call last):
  File "/home/gaoi/.virtualenvs/mytaste/lib/python3.6/site-packages/django/db/backends/utils.py", line 86, in _execute
    return self.cursor.execute(sql, params)
  File "/home/gaoi/.virtualenvs/mytaste/lib/python3.6/site-packages/django/db/backends/mysql/base.py", line 74, in execute
    return self.cursor.execute(query, args)
  File "/home/gaoi/.virtualenvs/mytaste/lib/python3.6/site-packages/MySQLdb/cursors.py", line 209, in execute
    res = self._query(query)
  File "/home/gaoi/.virtualenvs/mytaste/lib/python3.6/site-packages/MySQLdb/cursors.py", line 315, in _query
    db.query(q)
  File "/home/gaoi/.virtualenvs/mytaste/lib/python3.6/site-packages/MySQLdb/connections.py", line 239, in query
    _mysql.connection.query(self, query)
MySQLdb._exceptions.ProgrammingError: (1146, "Table 'myTaste.django_session' doesn't exist")

The above exception was the direct cause of the following exception:

Traceback (most recent call last):
  File "/home/gaoi/.virtualenvs/mytaste/lib/python3.6/site-packages/django/core/handlers/exception.py", line 34, in inner
    response = get_response(request)
  File "/home/gaoi/.virtualenvs/mytaste/lib/python3.6/site-packages/django/core/handlers/base.py", line 115, in _get_response
    response = self.process_exception_by_middleware(e, request)
  File "/home/gaoi/.virtualenvs/mytaste/lib/python3.6/site-packages/django/core/handlers/base.py", line 113, in _get_response
    response = wrapped_callback(request, *callback_args, **callback_kwargs)
  File "/home/gaoi/.virtualenvs/mytaste/lib/python3.6/site-packages/django/contrib/admin/sites.py", line 249, in wrapper
    return self.admin_view(view, cacheable)(*args, **kwargs)
  File "/home/gaoi/.virtualenvs/mytaste/lib/python3.6/site-packages/django/utils/decorators.py", line 130, in _wrapped_view
    response = view_func(request, *args, **kwargs)
  File "/home/gaoi/.virtualenvs/mytaste/lib/python3.6/site-packages/django/views/decorators/cache.py", line 44, in _wrapped_view_func
    response = view_func(request, *args, **kwargs)
  File "/home/gaoi/.virtualenvs/mytaste/lib/python3.6/site-packages/django/contrib/admin/sites.py", line 220, in inner
    if not self.has_permission(request):
  File "/home/gaoi/.virtualenvs/mytaste/lib/python3.6/site-packages/django/contrib/admin/sites.py", line 194, in has_permission
    return request.user.is_active and request.user.is_staff
  File "/home/gaoi/.virtualenvs/mytaste/lib/python3.6/site-packages/django/utils/functional.py", line 224, in inner
    self._setup()
  File "/home/gaoi/.virtualenvs/mytaste/lib/python3.6/site-packages/django/utils/functional.py", line 360, in _setup
    self._wrapped = self._setupfunc()
  File "/home/gaoi/.virtualenvs/mytaste/lib/python3.6/site-packages/django/contrib/auth/middleware.py", line 24, in <lambda>
    request.user = SimpleLazyObject(lambda: get_user(request))
  File "/home/gaoi/.virtualenvs/mytaste/lib/python3.6/site-packages/django/contrib/auth/middleware.py", line 12, in get_user
    request._cached_user = auth.get_user(request)
  File "/home/gaoi/.virtualenvs/mytaste/lib/python3.6/site-packages/django/contrib/auth/__init__.py", line 173, in get_user
    user_id = _get_user_session_key(request)
  File "/home/gaoi/.virtualenvs/mytaste/lib/python3.6/site-packages/django/contrib/auth/__init__.py", line 58, in _get_user_session_key
    return get_user_model()._meta.pk.to_python(request.session[SESSION_KEY])
  File "/home/gaoi/.virtualenvs/mytaste/lib/python3.6/site-packages/django/contrib/sessions/backends/base.py", line 64, in __getitem__
    return self._session[key]
  File "/home/gaoi/.virtualenvs/mytaste/lib/python3.6/site-packages/django/contrib/sessions/backends/base.py", line 204, in _get_session
    self._session_cache = self.load()
  File "/home/gaoi/.virtualenvs/mytaste/lib/python3.6/site-packages/django/contrib/sessions/backends/db.py", line 43, in load
    s = self._get_session_from_db()
  File "/home/gaoi/.virtualenvs/mytaste/lib/python3.6/site-packages/django/contrib/sessions/backends/db.py", line 34, in _get_session_from_db
    expire_date__gt=timezone.now()
  File "/home/gaoi/.virtualenvs/mytaste/lib/python3.6/site-packages/django/db/models/manager.py", line 82, in manager_method
    return getattr(self.get_queryset(), name)(*args, **kwargs)
  File "/home/gaoi/.virtualenvs/mytaste/lib/python3.6/site-packages/django/db/models/query.py", line 411, in get
    num = len(clone)
  File "/home/gaoi/.virtualenvs/mytaste/lib/python3.6/site-packages/django/db/models/query.py", line 258, in __len__
    self._fetch_all()
  File "/home/gaoi/.virtualenvs/mytaste/lib/python3.6/site-packages/django/db/models/query.py", line 1261, in _fetch_all
    self._result_cache = list(self._iterable_class(self))
  File "/home/gaoi/.virtualenvs/mytaste/lib/python3.6/site-packages/django/db/models/query.py", line 57, in __iter__
    results = compiler.execute_sql(chunked_fetch=self.chunked_fetch, chunk_size=self.chunk_size)
  File "/home/gaoi/.virtualenvs/mytaste/lib/python3.6/site-packages/django/db/models/sql/compiler.py", line 1151, in execute_sql
    cursor.execute(sql, params)
  File "/home/gaoi/.virtualenvs/mytaste/lib/python3.6/site-packages/django/db/backends/utils.py", line 100, in execute
    return super().execute(sql, params)
  File "/home/gaoi/.virtualenvs/mytaste/lib/python3.6/site-packages/django/db/backends/utils.py", line 68, in execute
    return self._execute_with_wrappers(sql, params, many=False, executor=self._execute)
  File "/home/gaoi/.virtualenvs/mytaste/lib/python3.6/site-packages/django/db/backends/utils.py", line 77, in _execute_with_wrappers
    return executor(sql, params, many, context)
  File "/home/gaoi/.virtualenvs/mytaste/lib/python3.6/site-packages/django/db/backends/utils.py", line 86, in _execute
    return self.cursor.execute(sql, params)
  File "/home/gaoi/.virtualenvs/mytaste/lib/python3.6/site-packages/django/db/utils.py", line 90, in __exit__
    raise dj_exc_value.with_traceback(traceback) from exc_value
  File "/home/gaoi/.virtualenvs/mytaste/lib/python3.6/site-packages/django/db/backends/utils.py", line 86, in _execute
    return self.cursor.execute(sql, params)
  File "/home/gaoi/.virtualenvs/mytaste/lib/python3.6/site-packages/django/db/backends/mysql/base.py", line 74, in execute
    return self.cursor.execute(query, args)
  File "/home/gaoi/.virtualenvs/mytaste/lib/python3.6/site-packages/MySQLdb/cursors.py", line 209, in execute
    res = self._query(query)
  File "/home/gaoi/.virtualenvs/mytaste/lib/python3.6/site-packages/MySQLdb/cursors.py", line 315, in _query
    db.query(q)
  File "/home/gaoi/.virtualenvs/mytaste/lib/python3.6/site-packages/MySQLdb/connections.py", line 239, in query
    _mysql.connection.query(self, query)
django.db.utils.ProgrammingError: (1146, "Table 'myTaste.django_session' doesn't exist")
{levelname} {asctime} {module} {process:d} {thread:d} {message}
{levelname} {asctime} {module} {process:d} {thread:d} {message}
Traceback (most recent call last):
  File "/home/gaoi/.virtualenvs/mytaste/lib/python3.6/site-packages/django/core/handlers/exception.py", line 34, in inner
    response = get_response(request)
  File "/home/gaoi/.virtualenvs/mytaste/lib/python3.6/site-packages/django/core/handlers/base.py", line 115, in _get_response
    response = self.process_exception_by_middleware(e, request)
  File "/home/gaoi/.virtualenvs/mytaste/lib/python3.6/site-packages/django/core/handlers/base.py", line 113, in _get_response
    response = wrapped_callback(request, *callback_args, **callback_kwargs)
  File "/home/gaoi/.virtualenvs/mytaste/lib/python3.6/site-packages/django/views/decorators/csrf.py", line 54, in wrapped_view
    return view_func(*args, **kwargs)
  File "/home/gaoi/.virtualenvs/mytaste/lib/python3.6/site-packages/django/views/generic/base.py", line 71, in view
    return self.dispatch(request, *args, **kwargs)
  File "/home/gaoi/.virtualenvs/mytaste/lib/python3.6/site-packages/django/views/generic/base.py", line 97, in dispatch
    return handler(request, *args, **kwargs)
  File "/home/gaoi/PycharmProjects/myTaste/mytasteapi/mytasteapi/apps/user/views.py", line 18, in post
    user = authenticate(request, username, password)
TypeError: authenticate() takes from 0 to 1 positional arguments but 3 were given
{levelname} {asctime} {module} {process:d} {thread:d} {message}
{levelname} {asctime} {module} {process:d} {thread:d} {message}
Traceback (most recent call last):
  File "/home/gaoi/.virtualenvs/mytaste/lib/python3.6/site-packages/django/core/handlers/exception.py", line 34, in inner
    response = get_response(request)
  File "/home/gaoi/.virtualenvs/mytaste/lib/python3.6/site-packages/django/core/handlers/base.py", line 115, in _get_response
    response = self.process_exception_by_middleware(e, request)
  File "/home/gaoi/.virtualenvs/mytaste/lib/python3.6/site-packages/django/core/handlers/base.py", line 113, in _get_response
    response = wrapped_callback(request, *callback_args, **callback_kwargs)
  File "/home/gaoi/.virtualenvs/mytaste/lib/python3.6/site-packages/django/views/decorators/csrf.py", line 54, in wrapped_view
    return view_func(*args, **kwargs)
  File "/home/gaoi/.virtualenvs/mytaste/lib/python3.6/site-packages/django/views/generic/base.py", line 71, in view
    return self.dispatch(request, *args, **kwargs)
  File "/home/gaoi/.virtualenvs/mytaste/lib/python3.6/site-packages/django/views/generic/base.py", line 97, in dispatch
    return handler(request, *args, **kwargs)
  File "/home/gaoi/PycharmProjects/myTaste/mytasteapi/mytasteapi/apps/user/views.py", line 18, in post
    user = authenticate(username=username, password=password)
  File "/home/gaoi/.virtualenvs/mytaste/lib/python3.6/site-packages/django/contrib/auth/__init__.py", line 65, in authenticate
    for backend, backend_path in _get_backends(return_tuples=True):
  File "/home/gaoi/.virtualenvs/mytaste/lib/python3.6/site-packages/django/contrib/auth/__init__.py", line 26, in _get_backends
    backend = load_backend(backend_path)
  File "/home/gaoi/.virtualenvs/mytaste/lib/python3.6/site-packages/django/contrib/auth/__init__.py", line 20, in load_backend
    return import_string(path)()
  File "/home/gaoi/.virtualenvs/mytaste/lib/python3.6/site-packages/django/utils/module_loading.py", line 17, in import_string
    module = import_module(module_path)
  File "/usr/lib/python3.6/importlib/__init__.py", line 126, in import_module
    return _bootstrap._gcd_import(name[level:], package, level)
  File "<frozen importlib._bootstrap>", line 994, in _gcd_import
  File "<frozen importlib._bootstrap>", line 971, in _find_and_load
  File "<frozen importlib._bootstrap>", line 955, in _find_and_load_unlocked
  File "<frozen importlib._bootstrap>", line 665, in _load_unlocked
  File "<frozen importlib._bootstrap_external>", line 678, in exec_module
  File "<frozen importlib._bootstrap>", line 219, in _call_with_frames_removed
  File "/home/gaoi/PycharmProjects/myTaste/mytasteapi/mytasteapi/apps/user/utils.py", line 7, in <module>
    from .models import User
  File "/home/gaoi/PycharmProjects/myTaste/mytasteapi/mytasteapi/apps/user/models.py", line 8, in <module>
    class User(AbstractUser):
  File "/home/gaoi/.virtualenvs/mytaste/lib/python3.6/site-packages/django/db/models/base.py", line 115, in __new__
    "INSTALLED_APPS." % (module, name)
RuntimeError: Model class mytasteapi.apps.user.models.User doesn't declare an explicit app_label and isn't in an application in INSTALLED_APPS.
{levelname} {asctime} {module} {process:d} {thread:d} {message}
{levelname} {asctime} {module} {process:d} {thread:d} {message}
Traceback (most recent call last):
  File "/home/gaoi/.virtualenvs/mytaste/lib/python3.6/site-packages/django/core/handlers/exception.py", line 34, in inner
    response = get_response(request)
  File "/home/gaoi/.virtualenvs/mytaste/lib/python3.6/site-packages/django/core/handlers/base.py", line 115, in _get_response
    response = self.process_exception_by_middleware(e, request)
  File "/home/gaoi/.virtualenvs/mytaste/lib/python3.6/site-packages/django/core/handlers/base.py", line 113, in _get_response
    response = wrapped_callback(request, *callback_args, **callback_kwargs)
  File "/home/gaoi/.virtualenvs/mytaste/lib/python3.6/site-packages/django/views/decorators/csrf.py", line 54, in wrapped_view
    return view_func(*args, **kwargs)
  File "/home/gaoi/.virtualenvs/mytaste/lib/python3.6/site-packages/django/views/generic/base.py", line 71, in view
    return self.dispatch(request, *args, **kwargs)
  File "/home/gaoi/.virtualenvs/mytaste/lib/python3.6/site-packages/django/views/generic/base.py", line 97, in dispatch
    return handler(request, *args, **kwargs)
  File "/home/gaoi/PycharmProjects/myTaste/mytasteapi/mytasteapi/apps/user/views.py", line 19, in post
    login(request, user)
  File "/home/gaoi/.virtualenvs/mytaste/lib/python3.6/site-packages/django/contrib/auth/__init__.py", line 125, in login
    request.session[SESSION_KEY] = user._meta.pk.value_to_string(user)
  File "/home/gaoi/.virtualenvs/mytaste/lib/python3.6/site-packages/django/utils/functional.py", line 225, in inner
    return func(self._wrapped, *args)
AttributeError: 'AnonymousUser' object has no attribute '_meta'
{levelname} {asctime} {module} {process:d} {thread:d} {message}
{levelname} {asctime} {module} {process:d} {thread:d} {message}
Traceback (most recent call last):
  File "/home/gaoi/.virtualenvs/mytaste/lib/python3.6/site-packages/django/core/handlers/exception.py", line 34, in inner
    response = get_response(request)
  File "/home/gaoi/.virtualenvs/mytaste/lib/python3.6/site-packages/django/core/handlers/base.py", line 115, in _get_response
    response = self.process_exception_by_middleware(e, request)
  File "/home/gaoi/.virtualenvs/mytaste/lib/python3.6/site-packages/django/core/handlers/base.py", line 113, in _get_response
    response = wrapped_callback(request, *callback_args, **callback_kwargs)
  File "/home/gaoi/.virtualenvs/mytaste/lib/python3.6/site-packages/django/views/decorators/csrf.py", line 54, in wrapped_view
    return view_func(*args, **kwargs)
  File "/home/gaoi/.virtualenvs/mytaste/lib/python3.6/site-packages/django/views/generic/base.py", line 71, in view
    return self.dispatch(request, *args, **kwargs)
  File "/home/gaoi/.virtualenvs/mytaste/lib/python3.6/site-packages/django/views/generic/base.py", line 97, in dispatch
    return handler(request, *args, **kwargs)
  File "/home/gaoi/PycharmProjects/myTaste/mytasteapi/mytasteapi/apps/user/views.py", line 19, in post
    login(request, user)
  File "/home/gaoi/.virtualenvs/mytaste/lib/python3.6/site-packages/django/contrib/auth/__init__.py", line 125, in login
    request.session[SESSION_KEY] = user._meta.pk.value_to_string(user)
  File "/home/gaoi/.virtualenvs/mytaste/lib/python3.6/site-packages/django/utils/functional.py", line 225, in inner
    return func(self._wrapped, *args)
AttributeError: 'AnonymousUser' object has no attribute '_meta'
{levelname} {asctime} {module} {process:d} {thread:d} {message}
{levelname} {asctime} {module} {process:d} {thread:d} {message}
Traceback (most recent call last):
  File "/home/gaoi/.virtualenvs/mytaste/lib/python3.6/site-packages/django/core/handlers/exception.py", line 34, in inner
    response = get_response(request)
  File "/home/gaoi/.virtualenvs/mytaste/lib/python3.6/site-packages/django/core/handlers/base.py", line 115, in _get_response
    response = self.process_exception_by_middleware(e, request)
  File "/home/gaoi/.virtualenvs/mytaste/lib/python3.6/site-packages/django/core/handlers/base.py", line 113, in _get_response
    response = wrapped_callback(request, *callback_args, **callback_kwargs)
  File "/home/gaoi/.virtualenvs/mytaste/lib/python3.6/site-packages/django/views/decorators/csrf.py", line 54, in wrapped_view
    return view_func(*args, **kwargs)
  File "/home/gaoi/.virtualenvs/mytaste/lib/python3.6/site-packages/django/views/generic/base.py", line 71, in view
    return self.dispatch(request, *args, **kwargs)
  File "/home/gaoi/.virtualenvs/mytaste/lib/python3.6/site-packages/django/views/generic/base.py", line 97, in dispatch
    return handler(request, *args, **kwargs)
  File "/home/gaoi/PycharmProjects/myTaste/mytasteapi/mytasteapi/apps/user/views.py", line 34, in post
    print(request.session['user'])
  File "/home/gaoi/.virtualenvs/mytaste/lib/python3.6/site-packages/django/contrib/sessions/backends/base.py", line 64, in __getitem__
    return self._session[key]
KeyError: 'user'
{levelname} {asctime} {module} {process:d} {thread:d} {message}
{levelname} {asctime} {module} {process:d} {thread:d} {message}
{levelname} {asctime} {module} {process:d} {thread:d} {message}
{levelname} {asctime} {module} {process:d} {thread:d} {message}
{levelname} {asctime} {module} {process:d} {thread:d} {message}
{levelname} {asctime} {module} {process:d} {thread:d} {message}
{levelname} {asctime} {module} {process:d} {thread:d} {message}
{levelname} {asctime} {module} {process:d} {thread:d} {message}
{levelname} {asctime} {module} {process:d} {thread:d} {message}
{levelname} {asctime} {module} {process:d} {thread:d} {message}
{levelname} {asctime} {module} {process:d} {thread:d} {message}
{levelname} {asctime} {module} {process:d} {thread:d} {message}
{levelname} {asctime} {module} {process:d} {thread:d} {message}
{levelname} {asctime} {module} {process:d} {thread:d} {message}
{levelname} {asctime} {module} {process:d} {thread:d} {message}
{levelname} {asctime} {module} {process:d} {thread:d} {message}
{levelname} {asctime} {module} {process:d} {thread:d} {message}
{levelname} {asctime} {module} {process:d} {thread:d} {message}
Traceback (most recent call last):
  File "/home/gaoi/.virtualenvs/mytaste/lib/python3.6/site-packages/django/core/handlers/exception.py", line 34, in inner
    response = get_response(request)
  File "/home/gaoi/.virtualenvs/mytaste/lib/python3.6/site-packages/django/core/handlers/base.py", line 115, in _get_response
    response = self.process_exception_by_middleware(e, request)
  File "/home/gaoi/.virtualenvs/mytaste/lib/python3.6/site-packages/django/core/handlers/base.py", line 113, in _get_response
    response = wrapped_callback(request, *callback_args, **callback_kwargs)
  File "/home/gaoi/.virtualenvs/mytaste/lib/python3.6/site-packages/django/contrib/admin/options.py", line 607, in wrapper
    return self.admin_site.admin_view(view)(*args, **kwargs)
  File "/home/gaoi/.virtualenvs/mytaste/lib/python3.6/site-packages/django/utils/decorators.py", line 130, in _wrapped_view
    response = view_func(request, *args, **kwargs)
  File "/home/gaoi/.virtualenvs/mytaste/lib/python3.6/site-packages/django/views/decorators/cache.py", line 44, in _wrapped_view_func
    response = view_func(request, *args, **kwargs)
  File "/home/gaoi/.virtualenvs/mytaste/lib/python3.6/site-packages/django/contrib/admin/sites.py", line 231, in inner
    return view(request, *args, **kwargs)
  File "/home/gaoi/.virtualenvs/mytaste/lib/python3.6/site-packages/django/contrib/admin/options.py", line 1641, in change_view
    return self.changeform_view(request, object_id, form_url, extra_context)
  File "/home/gaoi/.virtualenvs/mytaste/lib/python3.6/site-packages/django/utils/decorators.py", line 43, in _wrapper
    return bound_method(*args, **kwargs)
  File "/home/gaoi/.virtualenvs/mytaste/lib/python3.6/site-packages/django/utils/decorators.py", line 130, in _wrapped_view
    response = view_func(request, *args, **kwargs)
  File "/home/gaoi/.virtualenvs/mytaste/lib/python3.6/site-packages/django/contrib/admin/options.py", line 1522, in changeform_view
    return self._changeform_view(request, object_id, form_url, extra_context)
  File "/home/gaoi/.virtualenvs/mytaste/lib/python3.6/site-packages/django/contrib/admin/options.py", line 1565, in _changeform_view
    self.save_model(request, new_object, form, not add)
  File "/home/gaoi/.virtualenvs/mytaste/lib/python3.6/site-packages/django/contrib/admin/options.py", line 1081, in save_model
    obj.save()
  File "/home/gaoi/.virtualenvs/mytaste/lib/python3.6/site-packages/django/contrib/auth/base_user.py", line 66, in save
    super().save(*args, **kwargs)
  File "/home/gaoi/.virtualenvs/mytaste/lib/python3.6/site-packages/django/db/models/base.py", line 746, in save
    force_update=force_update, update_fields=update_fields)
  File "/home/gaoi/.virtualenvs/mytaste/lib/python3.6/site-packages/django/db/models/base.py", line 784, in save_base
    force_update, using, update_fields,
  File "/home/gaoi/.virtualenvs/mytaste/lib/python3.6/site-packages/django/db/models/base.py", line 862, in _save_table
    for f in non_pks]
  File "/home/gaoi/.virtualenvs/mytaste/lib/python3.6/site-packages/django/db/models/base.py", line 862, in <listcomp>
    for f in non_pks]
  File "/home/gaoi/.virtualenvs/mytaste/lib/python3.6/site-packages/django/db/models/fields/files.py", line 288, in pre_save
    file.save(file.name, file.file, save=False)
  File "/home/gaoi/.virtualenvs/mytaste/lib/python3.6/site-packages/django/db/models/fields/files.py", line 86, in save
    name = self.field.generate_filename(self.instance, name)
  File "/home/gaoi/.virtualenvs/mytaste/lib/python3.6/site-packages/django/db/models/fields/files.py", line 303, in generate_filename
    filename = self.upload_to(instance, filename)
  File "/home/gaoi/PycharmProjects/myTaste/mytasteapi/mytasteapi/apps/user/models.py", line 18, in user_directory_path
    return os.path.join(instance.user.id, "avatar", filename)
AttributeError: 'User' object has no attribute 'user'
{levelname} {asctime} {module} {process:d} {thread:d} {message}
{levelname} {asctime} {module} {process:d} {thread:d} {message}
Traceback (most recent call last):
  File "/home/gaoi/.virtualenvs/mytaste/lib/python3.6/site-packages/django/core/handlers/exception.py", line 34, in inner
    response = get_response(request)
  File "/home/gaoi/.virtualenvs/mytaste/lib/python3.6/site-packages/django/core/handlers/base.py", line 115, in _get_response
    response = self.process_exception_by_middleware(e, request)
  File "/home/gaoi/.virtualenvs/mytaste/lib/python3.6/site-packages/django/core/handlers/base.py", line 113, in _get_response
    response = wrapped_callback(request, *callback_args, **callback_kwargs)
  File "/home/gaoi/.virtualenvs/mytaste/lib/python3.6/site-packages/django/contrib/admin/options.py", line 607, in wrapper
    return self.admin_site.admin_view(view)(*args, **kwargs)
  File "/home/gaoi/.virtualenvs/mytaste/lib/python3.6/site-packages/django/utils/decorators.py", line 130, in _wrapped_view
    response = view_func(request, *args, **kwargs)
  File "/home/gaoi/.virtualenvs/mytaste/lib/python3.6/site-packages/django/views/decorators/cache.py", line 44, in _wrapped_view_func
    response = view_func(request, *args, **kwargs)
  File "/home/gaoi/.virtualenvs/mytaste/lib/python3.6/site-packages/django/contrib/admin/sites.py", line 231, in inner
    return view(request, *args, **kwargs)
  File "/home/gaoi/.virtualenvs/mytaste/lib/python3.6/site-packages/django/contrib/admin/options.py", line 1641, in change_view
    return self.changeform_view(request, object_id, form_url, extra_context)
  File "/home/gaoi/.virtualenvs/mytaste/lib/python3.6/site-packages/django/utils/decorators.py", line 43, in _wrapper
    return bound_method(*args, **kwargs)
  File "/home/gaoi/.virtualenvs/mytaste/lib/python3.6/site-packages/django/utils/decorators.py", line 130, in _wrapped_view
    response = view_func(request, *args, **kwargs)
  File "/home/gaoi/.virtualenvs/mytaste/lib/python3.6/site-packages/django/contrib/admin/options.py", line 1522, in changeform_view
    return self._changeform_view(request, object_id, form_url, extra_context)
  File "/home/gaoi/.virtualenvs/mytaste/lib/python3.6/site-packages/django/contrib/admin/options.py", line 1565, in _changeform_view
    self.save_model(request, new_object, form, not add)
  File "/home/gaoi/.virtualenvs/mytaste/lib/python3.6/site-packages/django/contrib/admin/options.py", line 1081, in save_model
    obj.save()
  File "/home/gaoi/.virtualenvs/mytaste/lib/python3.6/site-packages/django/contrib/auth/base_user.py", line 66, in save
    super().save(*args, **kwargs)
  File "/home/gaoi/.virtualenvs/mytaste/lib/python3.6/site-packages/django/db/models/base.py", line 746, in save
    force_update=force_update, update_fields=update_fields)
  File "/home/gaoi/.virtualenvs/mytaste/lib/python3.6/site-packages/django/db/models/base.py", line 784, in save_base
    force_update, using, update_fields,
  File "/home/gaoi/.virtualenvs/mytaste/lib/python3.6/site-packages/django/db/models/base.py", line 862, in _save_table
    for f in non_pks]
  File "/home/gaoi/.virtualenvs/mytaste/lib/python3.6/site-packages/django/db/models/base.py", line 862, in <listcomp>
    for f in non_pks]
  File "/home/gaoi/.virtualenvs/mytaste/lib/python3.6/site-packages/django/db/models/fields/files.py", line 288, in pre_save
    file.save(file.name, file.file, save=False)
  File "/home/gaoi/.virtualenvs/mytaste/lib/python3.6/site-packages/django/db/models/fields/files.py", line 86, in save
    name = self.field.generate_filename(self.instance, name)
  File "/home/gaoi/.virtualenvs/mytaste/lib/python3.6/site-packages/django/db/models/fields/files.py", line 303, in generate_filename
    filename = self.upload_to(instance, filename)
  File "/home/gaoi/PycharmProjects/myTaste/mytasteapi/mytasteapi/apps/user/models.py", line 18, in user_directory_path
    return os.path.join(instance.user.id, "avatar", filename)
AttributeError: 'User' object has no attribute 'user'
{levelname} {asctime} {module} {process:d} {thread:d} {message}
{levelname} {asctime} {module} {process:d} {thread:d} {message}
Traceback (most recent call last):
  File "/home/gaoi/.virtualenvs/mytaste/lib/python3.6/site-packages/django/core/handlers/exception.py", line 34, in inner
    response = get_response(request)
  File "/home/gaoi/.virtualenvs/mytaste/lib/python3.6/site-packages/django/core/handlers/base.py", line 115, in _get_response
    response = self.process_exception_by_middleware(e, request)
  File "/home/gaoi/.virtualenvs/mytaste/lib/python3.6/site-packages/django/core/handlers/base.py", line 113, in _get_response
    response = wrapped_callback(request, *callback_args, **callback_kwargs)
  File "/home/gaoi/.virtualenvs/mytaste/lib/python3.6/site-packages/django/contrib/admin/options.py", line 607, in wrapper
    return self.admin_site.admin_view(view)(*args, **kwargs)
  File "/home/gaoi/.virtualenvs/mytaste/lib/python3.6/site-packages/django/utils/decorators.py", line 130, in _wrapped_view
    response = view_func(request, *args, **kwargs)
  File "/home/gaoi/.virtualenvs/mytaste/lib/python3.6/site-packages/django/views/decorators/cache.py", line 44, in _wrapped_view_func
    response = view_func(request, *args, **kwargs)
  File "/home/gaoi/.virtualenvs/mytaste/lib/python3.6/site-packages/django/contrib/admin/sites.py", line 231, in inner
    return view(request, *args, **kwargs)
  File "/home/gaoi/.virtualenvs/mytaste/lib/python3.6/site-packages/django/contrib/admin/options.py", line 1641, in change_view
    return self.changeform_view(request, object_id, form_url, extra_context)
  File "/home/gaoi/.virtualenvs/mytaste/lib/python3.6/site-packages/django/utils/decorators.py", line 43, in _wrapper
    return bound_method(*args, **kwargs)
  File "/home/gaoi/.virtualenvs/mytaste/lib/python3.6/site-packages/django/utils/decorators.py", line 130, in _wrapped_view
    response = view_func(request, *args, **kwargs)
  File "/home/gaoi/.virtualenvs/mytaste/lib/python3.6/site-packages/django/contrib/admin/options.py", line 1522, in changeform_view
    return self._changeform_view(request, object_id, form_url, extra_context)
  File "/home/gaoi/.virtualenvs/mytaste/lib/python3.6/site-packages/django/contrib/admin/options.py", line 1565, in _changeform_view
    self.save_model(request, new_object, form, not add)
  File "/home/gaoi/.virtualenvs/mytaste/lib/python3.6/site-packages/django/contrib/admin/options.py", line 1081, in save_model
    obj.save()
  File "/home/gaoi/.virtualenvs/mytaste/lib/python3.6/site-packages/django/contrib/auth/base_user.py", line 66, in save
    super().save(*args, **kwargs)
  File "/home/gaoi/.virtualenvs/mytaste/lib/python3.6/site-packages/django/db/models/base.py", line 746, in save
    force_update=force_update, update_fields=update_fields)
  File "/home/gaoi/.virtualenvs/mytaste/lib/python3.6/site-packages/django/db/models/base.py", line 784, in save_base
    force_update, using, update_fields,
  File "/home/gaoi/.virtualenvs/mytaste/lib/python3.6/site-packages/django/db/models/base.py", line 862, in _save_table
    for f in non_pks]
  File "/home/gaoi/.virtualenvs/mytaste/lib/python3.6/site-packages/django/db/models/base.py", line 862, in <listcomp>
    for f in non_pks]
  File "/home/gaoi/.virtualenvs/mytaste/lib/python3.6/site-packages/django/db/models/fields/files.py", line 288, in pre_save
    file.save(file.name, file.file, save=False)
  File "/home/gaoi/.virtualenvs/mytaste/lib/python3.6/site-packages/django/db/models/fields/files.py", line 86, in save
    name = self.field.generate_filename(self.instance, name)
  File "/home/gaoi/.virtualenvs/mytaste/lib/python3.6/site-packages/django/db/models/fields/files.py", line 303, in generate_filename
    filename = self.upload_to(instance, filename)
  File "/home/gaoi/PycharmProjects/myTaste/mytasteapi/mytasteapi/apps/user/models.py", line 18, in user_directory_path
    return os.path.join(instance.id, "avatar", filename)
  File "/usr/lib/python3.6/posixpath.py", line 80, in join
    a = os.fspath(a)
TypeError: expected str, bytes or os.PathLike object, not int
{levelname} {asctime} {module} {process:d} {thread:d} {message}
{levelname} {asctime} {module} {process:d} {thread:d} {message}
{levelname} {asctime} {module} {process:d} {thread:d} {message}
{levelname} {asctime} {module} {process:d} {thread:d} {message}
{levelname} {asctime} {module} {process:d} {thread:d} {message}
{levelname} {asctime} {module} {process:d} {thread:d} {message}
{levelname} {asctime} {module} {process:d} {thread:d} {message}
{levelname} {asctime} {module} {process:d} {thread:d} {message}
{levelname} {asctime} {module} {process:d} {thread:d} {message}
{levelname} {asctime} {module} {process:d} {thread:d} {message}
{levelname} {asctime} {module} {process:d} {thread:d} {message}
{levelname} {asctime} {module} {process:d} {thread:d} {message}
{levelname} {asctime} {module} {process:d} {thread:d} {message}
{levelname} {asctime} {module} {process:d} {thread:d} {message}
{levelname} {asctime} {module} {process:d} {thread:d} {message}
{levelname} {asctime} {module} {process:d} {thread:d} {message}
Traceback (most recent call last):
  File "/home/gaoi/.virtualenvs/mytaste/lib/python3.6/site-packages/django/core/handlers/exception.py", line 34, in inner
    response = get_response(request)
  File "/home/gaoi/.virtualenvs/mytaste/lib/python3.6/site-packages/django/core/handlers/base.py", line 145, in _get_response
    response = self.process_exception_by_middleware(e, request)
  File "/home/gaoi/.virtualenvs/mytaste/lib/python3.6/site-packages/django/core/handlers/base.py", line 143, in _get_response
    response = response.render()
  File "/home/gaoi/.virtualenvs/mytaste/lib/python3.6/site-packages/django/template/response.py", line 105, in render
    self.content = self.rendered_content
  File "/home/gaoi/.virtualenvs/mytaste/lib/python3.6/site-packages/rest_framework/response.py", line 70, in rendered_content
    ret = renderer.render(self.data, accepted_media_type, context)
  File "/home/gaoi/.virtualenvs/mytaste/lib/python3.6/site-packages/rest_framework/renderers.py", line 103, in render
    allow_nan=not self.strict, separators=separators
  File "/home/gaoi/.virtualenvs/mytaste/lib/python3.6/site-packages/rest_framework/utils/json.py", line 25, in dumps
    return json.dumps(*args, **kwargs)
  File "/usr/lib/python3.6/json/__init__.py", line 238, in dumps
    **kw).encode(obj)
  File "/usr/lib/python3.6/json/encoder.py", line 199, in encode
    chunks = self.iterencode(o, _one_shot=True)
  File "/usr/lib/python3.6/json/encoder.py", line 257, in iterencode
    return _iterencode(o, 0)
  File "/home/gaoi/.virtualenvs/mytaste/lib/python3.6/site-packages/rest_framework/utils/encoders.py", line 50, in default
    return obj.decode()
UnicodeDecodeError: 'utf-8' codec can't decode byte 0xff in position 0: invalid start byte
{levelname} {asctime} {module} {process:d} {thread:d} {message}
{levelname} {asctime} {module} {process:d} {thread:d} {message}
Traceback (most recent call last):
  File "/home/gaoi/.virtualenvs/mytaste/lib/python3.6/site-packages/django/core/handlers/exception.py", line 34, in inner
    response = get_response(request)
  File "/home/gaoi/.virtualenvs/mytaste/lib/python3.6/site-packages/django/core/handlers/base.py", line 145, in _get_response
    response = self.process_exception_by_middleware(e, request)
  File "/home/gaoi/.virtualenvs/mytaste/lib/python3.6/site-packages/django/core/handlers/base.py", line 143, in _get_response
    response = response.render()
  File "/home/gaoi/.virtualenvs/mytaste/lib/python3.6/site-packages/django/template/response.py", line 105, in render
    self.content = self.rendered_content
  File "/home/gaoi/.virtualenvs/mytaste/lib/python3.6/site-packages/rest_framework/response.py", line 70, in rendered_content
    ret = renderer.render(self.data, accepted_media_type, context)
  File "/home/gaoi/.virtualenvs/mytaste/lib/python3.6/site-packages/rest_framework/renderers.py", line 103, in render
    allow_nan=not self.strict, separators=separators
  File "/home/gaoi/.virtualenvs/mytaste/lib/python3.6/site-packages/rest_framework/utils/json.py", line 25, in dumps
    return json.dumps(*args, **kwargs)
  File "/usr/lib/python3.6/json/__init__.py", line 238, in dumps
    **kw).encode(obj)
  File "/usr/lib/python3.6/json/encoder.py", line 199, in encode
    chunks = self.iterencode(o, _one_shot=True)
  File "/usr/lib/python3.6/json/encoder.py", line 257, in iterencode
    return _iterencode(o, 0)
  File "/home/gaoi/.virtualenvs/mytaste/lib/python3.6/site-packages/rest_framework/utils/encoders.py", line 50, in default
    return obj.decode()
UnicodeDecodeError: 'utf-8' codec can't decode byte 0xff in position 0: invalid start byte
{levelname} {asctime} {module} {process:d} {thread:d} {message}
{levelname} {asctime} {module} {process:d} {thread:d} {message}
Traceback (most recent call last):
  File "/home/gaoi/.virtualenvs/mytaste/lib/python3.6/site-packages/django/core/handlers/exception.py", line 34, in inner
    response = get_response(request)
  File "/home/gaoi/.virtualenvs/mytaste/lib/python3.6/site-packages/django/core/handlers/base.py", line 145, in _get_response
    response = self.process_exception_by_middleware(e, request)
  File "/home/gaoi/.virtualenvs/mytaste/lib/python3.6/site-packages/django/core/handlers/base.py", line 143, in _get_response
    response = response.render()
  File "/home/gaoi/.virtualenvs/mytaste/lib/python3.6/site-packages/django/template/response.py", line 105, in render
    self.content = self.rendered_content
  File "/home/gaoi/.virtualenvs/mytaste/lib/python3.6/site-packages/rest_framework/response.py", line 70, in rendered_content
    ret = renderer.render(self.data, accepted_media_type, context)
  File "/home/gaoi/.virtualenvs/mytaste/lib/python3.6/site-packages/rest_framework/renderers.py", line 103, in render
    allow_nan=not self.strict, separators=separators
  File "/home/gaoi/.virtualenvs/mytaste/lib/python3.6/site-packages/rest_framework/utils/json.py", line 25, in dumps
    return json.dumps(*args, **kwargs)
  File "/usr/lib/python3.6/json/__init__.py", line 238, in dumps
    **kw).encode(obj)
  File "/usr/lib/python3.6/json/encoder.py", line 199, in encode
    chunks = self.iterencode(o, _one_shot=True)
  File "/usr/lib/python3.6/json/encoder.py", line 257, in iterencode
    return _iterencode(o, 0)
  File "/home/gaoi/.virtualenvs/mytaste/lib/python3.6/site-packages/rest_framework/utils/encoders.py", line 50, in default
    return obj.decode()
UnicodeDecodeError: 'utf-8' codec can't decode byte 0xff in position 0: invalid start byte
{levelname} {asctime} {module} {process:d} {thread:d} {message}
{levelname} {asctime} {module} {process:d} {thread:d} {message}
{levelname} {asctime} {module} {process:d} {thread:d} {message}
{levelname} {asctime} {module} {process:d} {thread:d} {message}
Traceback (most recent call last):
  File "/home/gaoi/.virtualenvs/mytaste/lib/python3.6/site-packages/django/core/handlers/exception.py", line 34, in inner
    response = get_response(request)
  File "/home/gaoi/.virtualenvs/mytaste/lib/python3.6/site-packages/django/core/handlers/base.py", line 145, in _get_response
    response = self.process_exception_by_middleware(e, request)
  File "/home/gaoi/.virtualenvs/mytaste/lib/python3.6/site-packages/django/core/handlers/base.py", line 143, in _get_response
    response = response.render()
  File "/home/gaoi/.virtualenvs/mytaste/lib/python3.6/site-packages/django/template/response.py", line 105, in render
    self.content = self.rendered_content
  File "/home/gaoi/.virtualenvs/mytaste/lib/python3.6/site-packages/rest_framework/response.py", line 70, in rendered_content
    ret = renderer.render(self.data, accepted_media_type, context)
  File "/home/gaoi/.virtualenvs/mytaste/lib/python3.6/site-packages/rest_framework/renderers.py", line 103, in render
    allow_nan=not self.strict, separators=separators
  File "/home/gaoi/.virtualenvs/mytaste/lib/python3.6/site-packages/rest_framework/utils/json.py", line 25, in dumps
    return json.dumps(*args, **kwargs)
  File "/usr/lib/python3.6/json/__init__.py", line 238, in dumps
    **kw).encode(obj)
  File "/usr/lib/python3.6/json/encoder.py", line 199, in encode
    chunks = self.iterencode(o, _one_shot=True)
  File "/usr/lib/python3.6/json/encoder.py", line 257, in iterencode
    return _iterencode(o, 0)
  File "/home/gaoi/.virtualenvs/mytaste/lib/python3.6/site-packages/rest_framework/utils/encoders.py", line 50, in default
    return obj.decode()
UnicodeDecodeError: 'utf-8' codec can't decode byte 0xff in position 0: invalid start byte
{levelname} {asctime} {module} {process:d} {thread:d} {message}
{levelname} {asctime} {module} {process:d} {thread:d} {message}
{levelname} {asctime} {module} {process:d} {thread:d} {message}
{levelname} {asctime} {module} {process:d} {thread:d} {message}
{levelname} {asctime} {module} {process:d} {thread:d} {message}
{levelname} {asctime} {module} {process:d} {thread:d} {message}
{levelname} {asctime} {module} {process:d} {thread:d} {message}
{levelname} {asctime} {module} {process:d} {thread:d} {message}
{levelname} {asctime} {module} {process:d} {thread:d} {message}
{levelname} {asctime} {module} {process:d} {thread:d} {message}
{levelname} {asctime} {module} {process:d} {thread:d} {message}
{levelname} {asctime} {module} {process:d} {thread:d} {message}
Traceback (most recent call last):
  File "/home/gaoi/.virtualenvs/mytaste/lib/python3.6/site-packages/django/core/handlers/exception.py", line 34, in inner
    response = get_response(request)
  File "/home/gaoi/.virtualenvs/mytaste/lib/python3.6/site-packages/django/core/handlers/base.py", line 115, in _get_response
    response = self.process_exception_by_middleware(e, request)
  File "/home/gaoi/.virtualenvs/mytaste/lib/python3.6/site-packages/django/core/handlers/base.py", line 113, in _get_response
    response = wrapped_callback(request, *callback_args, **callback_kwargs)
  File "/home/gaoi/.virtualenvs/mytaste/lib/python3.6/site-packages/django/views/decorators/csrf.py", line 54, in wrapped_view
    return view_func(*args, **kwargs)
  File "/home/gaoi/.virtualenvs/mytaste/lib/python3.6/site-packages/django/views/generic/base.py", line 71, in view
    return self.dispatch(request, *args, **kwargs)
  File "/home/gaoi/.virtualenvs/mytaste/lib/python3.6/site-packages/rest_framework/views.py", line 505, in dispatch
    response = self.handle_exception(exc)
  File "/home/gaoi/.virtualenvs/mytaste/lib/python3.6/site-packages/rest_framework/views.py", line 465, in handle_exception
    self.raise_uncaught_exception(exc)
  File "/home/gaoi/.virtualenvs/mytaste/lib/python3.6/site-packages/rest_framework/views.py", line 476, in raise_uncaught_exception
    raise exc
  File "/home/gaoi/.virtualenvs/mytaste/lib/python3.6/site-packages/rest_framework/views.py", line 502, in dispatch
    response = handler(request, *args, **kwargs)
  File "/home/gaoi/.virtualenvs/mytaste/lib/python3.6/site-packages/rest_framework/generics.py", line 190, in post
    return self.create(request, *args, **kwargs)
  File "/home/gaoi/.virtualenvs/mytaste/lib/python3.6/site-packages/rest_framework/mixins.py", line 19, in create
    self.perform_create(serializer)
  File "/home/gaoi/.virtualenvs/mytaste/lib/python3.6/site-packages/rest_framework/mixins.py", line 24, in perform_create
    serializer.save()
  File "/home/gaoi/.virtualenvs/mytaste/lib/python3.6/site-packages/rest_framework/serializers.py", line 212, in save
    self.instance = self.create(validated_data)
  File "/home/gaoi/PycharmProjects/myTaste/mytasteapi/mytasteapi/apps/user/serializers.py", line 49, in create
    validated_data.pop("ses_code")
KeyError: 'ses_code'
{levelname} {asctime} {module} {process:d} {thread:d} {message}
{levelname} {asctime} {module} {process:d} {thread:d} {message}
{levelname} {asctime} {module} {process:d} {thread:d} {message}
{levelname} {asctime} {module} {process:d} {thread:d} {message}
{levelname} {asctime} {module} {process:d} {thread:d} {message}
{levelname} {asctime} {module} {process:d} {thread:d} {message}
Traceback (most recent call last):
  File "/home/gaoi/.virtualenvs/mytaste/lib/python3.6/site-packages/django/core/handlers/exception.py", line 34, in inner
    response = get_response(request)
  File "/home/gaoi/.virtualenvs/mytaste/lib/python3.6/site-packages/django/core/handlers/base.py", line 115, in _get_response
    response = self.process_exception_by_middleware(e, request)
  File "/home/gaoi/.virtualenvs/mytaste/lib/python3.6/site-packages/django/core/handlers/base.py", line 113, in _get_response
    response = wrapped_callback(request, *callback_args, **callback_kwargs)
  File "/home/gaoi/.virtualenvs/mytaste/lib/python3.6/site-packages/django/views/decorators/csrf.py", line 54, in wrapped_view
    return view_func(*args, **kwargs)
  File "/home/gaoi/.virtualenvs/mytaste/lib/python3.6/site-packages/django/views/generic/base.py", line 71, in view
    return self.dispatch(request, *args, **kwargs)
  File "/home/gaoi/.virtualenvs/mytaste/lib/python3.6/site-packages/rest_framework/views.py", line 505, in dispatch
    response = self.handle_exception(exc)
  File "/home/gaoi/.virtualenvs/mytaste/lib/python3.6/site-packages/rest_framework/views.py", line 465, in handle_exception
    self.raise_uncaught_exception(exc)
  File "/home/gaoi/.virtualenvs/mytaste/lib/python3.6/site-packages/rest_framework/views.py", line 476, in raise_uncaught_exception
    raise exc
  File "/home/gaoi/.virtualenvs/mytaste/lib/python3.6/site-packages/rest_framework/views.py", line 502, in dispatch
    response = handler(request, *args, **kwargs)
  File "/home/gaoi/.virtualenvs/mytaste/lib/python3.6/site-packages/rest_framework/generics.py", line 190, in post
    return self.create(request, *args, **kwargs)
  File "/home/gaoi/.virtualenvs/mytaste/lib/python3.6/site-packages/rest_framework/mixins.py", line 19, in create
    self.perform_create(serializer)
  File "/home/gaoi/.virtualenvs/mytaste/lib/python3.6/site-packages/rest_framework/mixins.py", line 24, in perform_create
    serializer.save()
  File "/home/gaoi/.virtualenvs/mytaste/lib/python3.6/site-packages/rest_framework/serializers.py", line 214, in save
    '`create()` did not return an object instance.'
AssertionError: `create()` did not return an object instance.
{levelname} {asctime} {module} {process:d} {thread:d} {message}
{levelname} {asctime} {module} {process:d} {thread:d} {message}
{levelname} {asctime} {module} {process:d} {thread:d} {message}
{levelname} {asctime} {module} {process:d} {thread:d} {message}
{levelname} {asctime} {module} {process:d} {thread:d} {message}
{levelname} {asctime} {module} {process:d} {thread:d} {message}
Traceback (most recent call last):
  File "/home/gaoi/.virtualenvs/mytaste/lib/python3.6/site-packages/django/core/handlers/exception.py", line 34, in inner
    response = get_response(request)
  File "/home/gaoi/.virtualenvs/mytaste/lib/python3.6/site-packages/django/core/handlers/base.py", line 115, in _get_response
    response = self.process_exception_by_middleware(e, request)
  File "/home/gaoi/.virtualenvs/mytaste/lib/python3.6/site-packages/django/core/handlers/base.py", line 113, in _get_response
    response = wrapped_callback(request, *callback_args, **callback_kwargs)
  File "/home/gaoi/.virtualenvs/mytaste/lib/python3.6/site-packages/django/views/decorators/csrf.py", line 54, in wrapped_view
    return view_func(*args, **kwargs)
  File "/home/gaoi/.virtualenvs/mytaste/lib/python3.6/site-packages/django/views/generic/base.py", line 71, in view
    return self.dispatch(request, *args, **kwargs)
  File "/home/gaoi/.virtualenvs/mytaste/lib/python3.6/site-packages/rest_framework/views.py", line 505, in dispatch
    response = self.handle_exception(exc)
  File "/home/gaoi/.virtualenvs/mytaste/lib/python3.6/site-packages/rest_framework/views.py", line 465, in handle_exception
    self.raise_uncaught_exception(exc)
  File "/home/gaoi/.virtualenvs/mytaste/lib/python3.6/site-packages/rest_framework/views.py", line 476, in raise_uncaught_exception
    raise exc
  File "/home/gaoi/.virtualenvs/mytaste/lib/python3.6/site-packages/rest_framework/views.py", line 502, in dispatch
    response = handler(request, *args, **kwargs)
  File "/home/gaoi/.virtualenvs/mytaste/lib/python3.6/site-packages/rest_framework/generics.py", line 190, in post
    return self.create(request, *args, **kwargs)
  File "/home/gaoi/.virtualenvs/mytaste/lib/python3.6/site-packages/rest_framework/mixins.py", line 19, in create
    self.perform_create(serializer)
  File "/home/gaoi/.virtualenvs/mytaste/lib/python3.6/site-packages/rest_framework/mixins.py", line 24, in perform_create
    serializer.save()
  File "/home/gaoi/.virtualenvs/mytaste/lib/python3.6/site-packages/rest_framework/serializers.py", line 212, in save
    self.instance = self.create(validated_data)
  File "/home/gaoi/PycharmProjects/myTaste/mytasteapi/mytasteapi/apps/user/serializers.py", line 58, in create
    jwt_payload_handler = api_settings.JWT_PAYLOAD_HANDLER
  File "/home/gaoi/.virtualenvs/mytaste/lib/python3.6/site-packages/rest_framework/settings.py", line 209, in __getattr__
    raise AttributeError("Invalid API setting: '%s'" % attr)
AttributeError: Invalid API setting: 'JWT_PAYLOAD_HANDLER'
{levelname} {asctime} {module} {process:d} {thread:d} {message}
{levelname} {asctime} {module} {process:d} {thread:d} {message}
{levelname} {asctime} {module} {process:d} {thread:d} {message}
{levelname} {asctime} {module} {process:d} {thread:d} {message}
{levelname} {asctime} {module} {process:d} {thread:d} {message}
{levelname} {asctime} {module} {process:d} {thread:d} {message}
Traceback (most recent call last):
  File "/home/gaoi/.virtualenvs/mytaste/lib/python3.6/site-packages/django/core/handlers/exception.py", line 34, in inner
    response = get_response(request)
  File "/home/gaoi/.virtualenvs/mytaste/lib/python3.6/site-packages/django/core/handlers/base.py", line 115, in _get_response
    response = self.process_exception_by_middleware(e, request)
  File "/home/gaoi/.virtualenvs/mytaste/lib/python3.6/site-packages/django/core/handlers/base.py", line 113, in _get_response
    response = wrapped_callback(request, *callback_args, **callback_kwargs)
  File "/home/gaoi/.virtualenvs/mytaste/lib/python3.6/site-packages/django/views/decorators/csrf.py", line 54, in wrapped_view
    return view_func(*args, **kwargs)
  File "/home/gaoi/.virtualenvs/mytaste/lib/python3.6/site-packages/django/views/generic/base.py", line 71, in view
    return self.dispatch(request, *args, **kwargs)
  File "/home/gaoi/.virtualenvs/mytaste/lib/python3.6/site-packages/rest_framework/views.py", line 505, in dispatch
    response = self.handle_exception(exc)
  File "/home/gaoi/.virtualenvs/mytaste/lib/python3.6/site-packages/rest_framework/views.py", line 465, in handle_exception
    self.raise_uncaught_exception(exc)
  File "/home/gaoi/.virtualenvs/mytaste/lib/python3.6/site-packages/rest_framework/views.py", line 476, in raise_uncaught_exception
    raise exc
  File "/home/gaoi/.virtualenvs/mytaste/lib/python3.6/site-packages/rest_framework/views.py", line 502, in dispatch
    response = handler(request, *args, **kwargs)
  File "/home/gaoi/.virtualenvs/mytaste/lib/python3.6/site-packages/rest_framework/generics.py", line 190, in post
    return self.create(request, *args, **kwargs)
  File "/home/gaoi/.virtualenvs/mytaste/lib/python3.6/site-packages/rest_framework/mixins.py", line 19, in create
    self.perform_create(serializer)
  File "/home/gaoi/.virtualenvs/mytaste/lib/python3.6/site-packages/rest_framework/mixins.py", line 24, in perform_create
    serializer.save()
  File "/home/gaoi/.virtualenvs/mytaste/lib/python3.6/site-packages/rest_framework/serializers.py", line 212, in save
    self.instance = self.create(validated_data)
  File "/home/gaoi/PycharmProjects/myTaste/mytasteapi/mytasteapi/apps/user/serializers.py", line 58, in create
    jwt_payload_handler = api_settings.JWT_PAYLOAD_HANDLER
  File "/home/gaoi/.virtualenvs/mytaste/lib/python3.6/site-packages/rest_framework/settings.py", line 209, in __getattr__
    raise AttributeError("Invalid API setting: '%s'" % attr)
AttributeError: Invalid API setting: 'JWT_PAYLOAD_HANDLER'
{levelname} {asctime} {module} {process:d} {thread:d} {message}
{levelname} {asctime} {module} {process:d} {thread:d} {message}
Traceback (most recent call last):
  File "/home/gaoi/.virtualenvs/mytaste/lib/python3.6/site-packages/django/core/handlers/exception.py", line 34, in inner
    response = get_response(request)
  File "/home/gaoi/.virtualenvs/mytaste/lib/python3.6/site-packages/django/core/handlers/base.py", line 115, in _get_response
    response = self.process_exception_by_middleware(e, request)
  File "/home/gaoi/.virtualenvs/mytaste/lib/python3.6/site-packages/django/core/handlers/base.py", line 113, in _get_response
    response = wrapped_callback(request, *callback_args, **callback_kwargs)
  File "/home/gaoi/.virtualenvs/mytaste/lib/python3.6/site-packages/django/views/decorators/csrf.py", line 54, in wrapped_view
    return view_func(*args, **kwargs)
  File "/home/gaoi/.virtualenvs/mytaste/lib/python3.6/site-packages/django/views/generic/base.py", line 71, in view
    return self.dispatch(request, *args, **kwargs)
  File "/home/gaoi/.virtualenvs/mytaste/lib/python3.6/site-packages/rest_framework/views.py", line 505, in dispatch
    response = self.handle_exception(exc)
  File "/home/gaoi/.virtualenvs/mytaste/lib/python3.6/site-packages/rest_framework/views.py", line 465, in handle_exception
    self.raise_uncaught_exception(exc)
  File "/home/gaoi/.virtualenvs/mytaste/lib/python3.6/site-packages/rest_framework/views.py", line 476, in raise_uncaught_exception
    raise exc
  File "/home/gaoi/.virtualenvs/mytaste/lib/python3.6/site-packages/rest_framework/views.py", line 502, in dispatch
    response = handler(request, *args, **kwargs)
  File "/home/gaoi/.virtualenvs/mytaste/lib/python3.6/site-packages/rest_framework/generics.py", line 190, in post
    return self.create(request, *args, **kwargs)
  File "/home/gaoi/.virtualenvs/mytaste/lib/python3.6/site-packages/rest_framework/mixins.py", line 19, in create
    self.perform_create(serializer)
  File "/home/gaoi/.virtualenvs/mytaste/lib/python3.6/site-packages/rest_framework/mixins.py", line 24, in perform_create
    serializer.save()
  File "/home/gaoi/.virtualenvs/mytaste/lib/python3.6/site-packages/rest_framework/serializers.py", line 212, in save
    self.instance = self.create(validated_data)
  File "/home/gaoi/PycharmProjects/myTaste/mytasteapi/mytasteapi/apps/user/serializers.py", line 58, in create
    jwt_payload_handler = api_settings.JWT_PAYLOAD_HANDLER
  File "/home/gaoi/.virtualenvs/mytaste/lib/python3.6/site-packages/rest_framework/settings.py", line 209, in __getattr__
    raise AttributeError("Invalid API setting: '%s'" % attr)
AttributeError: Invalid API setting: 'JWT_PAYLOAD_HANDLER'
{levelname} {asctime} {module} {process:d} {thread:d} {message}
{levelname} {asctime} {module} {process:d} {thread:d} {message}
Traceback (most recent call last):
  File "/home/gaoi/.virtualenvs/mytaste/lib/python3.6/site-packages/django/core/handlers/exception.py", line 34, in inner
    response = get_response(request)
  File "/home/gaoi/.virtualenvs/mytaste/lib/python3.6/site-packages/django/core/handlers/base.py", line 115, in _get_response
    response = self.process_exception_by_middleware(e, request)
  File "/home/gaoi/.virtualenvs/mytaste/lib/python3.6/site-packages/django/core/handlers/base.py", line 113, in _get_response
    response = wrapped_callback(request, *callback_args, **callback_kwargs)
  File "/home/gaoi/.virtualenvs/mytaste/lib/python3.6/site-packages/django/views/decorators/csrf.py", line 54, in wrapped_view
    return view_func(*args, **kwargs)
  File "/home/gaoi/.virtualenvs/mytaste/lib/python3.6/site-packages/django/views/generic/base.py", line 71, in view
    return self.dispatch(request, *args, **kwargs)
  File "/home/gaoi/.virtualenvs/mytaste/lib/python3.6/site-packages/rest_framework/views.py", line 505, in dispatch
    response = self.handle_exception(exc)
  File "/home/gaoi/.virtualenvs/mytaste/lib/python3.6/site-packages/rest_framework/views.py", line 465, in handle_exception
    self.raise_uncaught_exception(exc)
  File "/home/gaoi/.virtualenvs/mytaste/lib/python3.6/site-packages/rest_framework/views.py", line 476, in raise_uncaught_exception
    raise exc
  File "/home/gaoi/.virtualenvs/mytaste/lib/python3.6/site-packages/rest_framework/views.py", line 502, in dispatch
    response = handler(request, *args, **kwargs)
  File "/home/gaoi/.virtualenvs/mytaste/lib/python3.6/site-packages/rest_framework/generics.py", line 190, in post
    return self.create(request, *args, **kwargs)
  File "/home/gaoi/.virtualenvs/mytaste/lib/python3.6/site-packages/rest_framework/mixins.py", line 19, in create
    self.perform_create(serializer)
  File "/home/gaoi/.virtualenvs/mytaste/lib/python3.6/site-packages/rest_framework/mixins.py", line 24, in perform_create
    serializer.save()
  File "/home/gaoi/.virtualenvs/mytaste/lib/python3.6/site-packages/rest_framework/serializers.py", line 212, in save
    self.instance = self.create(validated_data)
  File "/home/gaoi/PycharmProjects/myTaste/mytasteapi/mytasteapi/apps/user/serializers.py", line 56, in create
    payload = serializers.jwt_payload_handler(user)
AttributeError: module 'rest_framework.serializers' has no attribute 'jwt_payload_handler'
{levelname} {asctime} {module} {process:d} {thread:d} {message}
{levelname} {asctime} {module} {process:d} {thread:d} {message}
Traceback (most recent call last):
  File "/home/gaoi/.virtualenvs/mytaste/lib/python3.6/site-packages/django/core/handlers/exception.py", line 34, in inner
    response = get_response(request)
  File "/home/gaoi/.virtualenvs/mytaste/lib/python3.6/site-packages/django/core/handlers/base.py", line 115, in _get_response
    response = self.process_exception_by_middleware(e, request)
  File "/home/gaoi/.virtualenvs/mytaste/lib/python3.6/site-packages/django/core/handlers/base.py", line 113, in _get_response
    response = wrapped_callback(request, *callback_args, **callback_kwargs)
  File "/home/gaoi/.virtualenvs/mytaste/lib/python3.6/site-packages/django/views/decorators/csrf.py", line 54, in wrapped_view
    return view_func(*args, **kwargs)
  File "/home/gaoi/.virtualenvs/mytaste/lib/python3.6/site-packages/django/views/generic/base.py", line 71, in view
    return self.dispatch(request, *args, **kwargs)
  File "/home/gaoi/.virtualenvs/mytaste/lib/python3.6/site-packages/rest_framework/views.py", line 505, in dispatch
    response = self.handle_exception(exc)
  File "/home/gaoi/.virtualenvs/mytaste/lib/python3.6/site-packages/rest_framework/views.py", line 465, in handle_exception
    self.raise_uncaught_exception(exc)
  File "/home/gaoi/.virtualenvs/mytaste/lib/python3.6/site-packages/rest_framework/views.py", line 476, in raise_uncaught_exception
    raise exc
  File "/home/gaoi/.virtualenvs/mytaste/lib/python3.6/site-packages/rest_framework/views.py", line 502, in dispatch
    response = handler(request, *args, **kwargs)
  File "/home/gaoi/.virtualenvs/mytaste/lib/python3.6/site-packages/rest_framework/generics.py", line 190, in post
    return self.create(request, *args, **kwargs)
  File "/home/gaoi/.virtualenvs/mytaste/lib/python3.6/site-packages/rest_framework/mixins.py", line 18, in create
    serializer.is_valid(raise_exception=True)
  File "/home/gaoi/.virtualenvs/mytaste/lib/python3.6/site-packages/rest_framework/serializers.py", line 234, in is_valid
    self._validated_data = self.run_validation(self.initial_data)
  File "/home/gaoi/.virtualenvs/mytaste/lib/python3.6/site-packages/rest_framework/serializers.py", line 436, in run_validation
    value = self.validate(value)
  File "/home/gaoi/PycharmProjects/myTaste/mytasteapi/mytasteapi/apps/user/serializers.py", line 40, in validate
    if not re.match(r"^1[3-9]\d{9}$", phone):
  File "/usr/lib/python3.6/re.py", line 172, in match
    return _compile(pattern, flags).match(string)
TypeError: expected string or bytes-like object
{levelname} {asctime} {module} {process:d} {thread:d} {message}
{levelname} {asctime} {module} {process:d} {thread:d} {message}
{levelname} {asctime} {module} {process:d} {thread:d} {message}
{levelname} {asctime} {module} {process:d} {thread:d} {message}
{levelname} {asctime} {module} {process:d} {thread:d} {message}
{levelname} {asctime} {module} {process:d} {thread:d} {message}
{levelname} {asctime} {module} {process:d} {thread:d} {message}
{levelname} {asctime} {module} {process:d} {thread:d} {message}
{levelname} {asctime} {module} {process:d} {thread:d} {message}
{levelname} {asctime} {module} {process:d} {thread:d} {message}
{levelname} {asctime} {module} {process:d} {thread:d} {message}
{levelname} {asctime} {module} {process:d} {thread:d} {message}
{levelname} {asctime} {module} {process:d} {thread:d} {message}
{levelname} {asctime} {module} {process:d} {thread:d} {message}
{levelname} {asctime} {module} {process:d} {thread:d} {message}
{levelname} {asctime} {module} {process:d} {thread:d} {message}
{levelname} {asctime} {module} {process:d} {thread:d} {message}
{levelname} {asctime} {module} {process:d} {thread:d} {message}
{levelname} {asctime} {module} {process:d} {thread:d} {message}
{levelname} {asctime} {module} {process:d} {thread:d} {message}
{levelname} {asctime} {module} {process:d} {thread:d} {message}
{levelname} {asctime} {module} {process:d} {thread:d} {message}
{levelname} {asctime} {module} {process:d} {thread:d} {message}
{levelname} {asctime} {module} {process:d} {thread:d} {message}
{levelname} {asctime} {module} {process:d} {thread:d} {message}
{levelname} {asctime} {module} {process:d} {thread:d} {message}
{levelname} {asctime} {module} {process:d} {thread:d} {message}
{levelname} {asctime} {module} {process:d} {thread:d} {message}
{levelname} {asctime} {module} {process:d} {thread:d} {message}
{levelname} {asctime} {module} {process:d} {thread:d} {message}
{levelname} {asctime} {module} {process:d} {thread:d} {message}
{levelname} {asctime} {module} {process:d} {thread:d} {message}
{levelname} {asctime} {module} {process:d} {thread:d} {message}
{levelname} {asctime} {module} {process:d} {thread:d} {message}
{levelname} {asctime} {module} {process:d} {thread:d} {message}
{levelname} {asctime} {module} {process:d} {thread:d} {message}
{levelname} {asctime} {module} {process:d} {thread:d} {message}
{levelname} {asctime} {module} {process:d} {thread:d} {message}
Traceback (most recent call last):
  File "/home/gaoi/.virtualenvs/mytaste/lib/python3.6/site-packages/django/core/handlers/exception.py", line 34, in inner
    response = get_response(request)
  File "/home/gaoi/.virtualenvs/mytaste/lib/python3.6/site-packages/django/core/handlers/base.py", line 115, in _get_response
    response = self.process_exception_by_middleware(e, request)
  File "/home/gaoi/.virtualenvs/mytaste/lib/python3.6/site-packages/django/core/handlers/base.py", line 113, in _get_response
    response = wrapped_callback(request, *callback_args, **callback_kwargs)
  File "/home/gaoi/.virtualenvs/mytaste/lib/python3.6/site-packages/django/views/decorators/csrf.py", line 54, in wrapped_view
    return view_func(*args, **kwargs)
  File "/home/gaoi/.virtualenvs/mytaste/lib/python3.6/site-packages/django/views/generic/base.py", line 71, in view
    return self.dispatch(request, *args, **kwargs)
  File "/home/gaoi/.virtualenvs/mytaste/lib/python3.6/site-packages/rest_framework/views.py", line 505, in dispatch
    response = self.handle_exception(exc)
  File "/home/gaoi/.virtualenvs/mytaste/lib/python3.6/site-packages/rest_framework/views.py", line 465, in handle_exception
    self.raise_uncaught_exception(exc)
  File "/home/gaoi/.virtualenvs/mytaste/lib/python3.6/site-packages/rest_framework/views.py", line 476, in raise_uncaught_exception
    raise exc
  File "/home/gaoi/.virtualenvs/mytaste/lib/python3.6/site-packages/rest_framework/views.py", line 502, in dispatch
    response = handler(request, *args, **kwargs)
  File "/home/gaoi/.virtualenvs/mytaste/lib/python3.6/site-packages/rest_framework/generics.py", line 199, in get
    return self.list(request, *args, **kwargs)
  File "/home/gaoi/.virtualenvs/mytaste/lib/python3.6/site-packages/rest_framework/mixins.py", line 38, in list
    queryset = self.filter_queryset(self.get_queryset())
  File "/home/gaoi/.virtualenvs/mytaste/lib/python3.6/site-packages/rest_framework/generics.py", line 150, in filter_queryset
    queryset = backend().filter_queryset(self.request, queryset, self)
AttributeError: 'OrderingFilter' object has no attribute 'filter_queryset'
{levelname} {asctime} {module} {process:d} {thread:d} {message}
{levelname} {asctime} {module} {process:d} {thread:d} {message}
{levelname} {asctime} {module} {process:d} {thread:d} {message}
{levelname} {asctime} {module} {process:d} {thread:d} {message}
Traceback (most recent call last):
  File "/home/gaoi/.virtualenvs/mytaste/lib/python3.6/site-packages/django/core/handlers/exception.py", line 34, in inner
    response = get_response(request)
  File "/home/gaoi/.virtualenvs/mytaste/lib/python3.6/site-packages/django/core/handlers/base.py", line 115, in _get_response
    response = self.process_exception_by_middleware(e, request)
  File "/home/gaoi/.virtualenvs/mytaste/lib/python3.6/site-packages/django/core/handlers/base.py", line 113, in _get_response
    response = wrapped_callback(request, *callback_args, **callback_kwargs)
  File "/home/gaoi/.virtualenvs/mytaste/lib/python3.6/site-packages/django/views/decorators/csrf.py", line 54, in wrapped_view
    return view_func(*args, **kwargs)
  File "/home/gaoi/.virtualenvs/mytaste/lib/python3.6/site-packages/django/views/generic/base.py", line 71, in view
    return self.dispatch(request, *args, **kwargs)
  File "/home/gaoi/.virtualenvs/mytaste/lib/python3.6/site-packages/rest_framework/views.py", line 505, in dispatch
    response = self.handle_exception(exc)
  File "/home/gaoi/.virtualenvs/mytaste/lib/python3.6/site-packages/rest_framework/views.py", line 465, in handle_exception
    self.raise_uncaught_exception(exc)
  File "/home/gaoi/.virtualenvs/mytaste/lib/python3.6/site-packages/rest_framework/views.py", line 476, in raise_uncaught_exception
    raise exc
  File "/home/gaoi/.virtualenvs/mytaste/lib/python3.6/site-packages/rest_framework/views.py", line 502, in dispatch
    response = handler(request, *args, **kwargs)
  File "/home/gaoi/.virtualenvs/mytaste/lib/python3.6/site-packages/rest_framework/generics.py", line 199, in get
    return self.list(request, *args, **kwargs)
  File "/home/gaoi/.virtualenvs/mytaste/lib/python3.6/site-packages/rest_framework/mixins.py", line 38, in list
    queryset = self.filter_queryset(self.get_queryset())
  File "/home/gaoi/.virtualenvs/mytaste/lib/python3.6/site-packages/rest_framework/generics.py", line 150, in filter_queryset
    queryset = backend().filter_queryset(self.request, queryset, self)
  File "/home/gaoi/.virtualenvs/mytaste/lib/python3.6/site-packages/rest_framework/filters.py", line 122, in filter_queryset
    queryset = queryset.filter(reduce(operator.and_, conditions))
  File "/home/gaoi/.virtualenvs/mytaste/lib/python3.6/site-packages/django/db/models/query.py", line 904, in filter
    return self._filter_or_exclude(False, *args, **kwargs)
  File "/home/gaoi/.virtualenvs/mytaste/lib/python3.6/site-packages/django/db/models/query.py", line 917, in _filter_or_exclude
    "Cannot filter a query once a slice has been taken."
AssertionError: Cannot filter a query once a slice has been taken.
{levelname} {asctime} {module} {process:d} {thread:d} {message}
{levelname} {asctime} {module} {process:d} {thread:d} {message}
Traceback (most recent call last):
  File "/home/gaoi/.virtualenvs/mytaste/lib/python3.6/site-packages/django/core/handlers/exception.py", line 34, in inner
    response = get_response(request)
  File "/home/gaoi/.virtualenvs/mytaste/lib/python3.6/site-packages/django/core/handlers/base.py", line 115, in _get_response
    response = self.process_exception_by_middleware(e, request)
  File "/home/gaoi/.virtualenvs/mytaste/lib/python3.6/site-packages/django/core/handlers/base.py", line 113, in _get_response
    response = wrapped_callback(request, *callback_args, **callback_kwargs)
  File "/home/gaoi/.virtualenvs/mytaste/lib/python3.6/site-packages/django/views/decorators/csrf.py", line 54, in wrapped_view
    return view_func(*args, **kwargs)
  File "/home/gaoi/.virtualenvs/mytaste/lib/python3.6/site-packages/django/views/generic/base.py", line 71, in view
    return self.dispatch(request, *args, **kwargs)
  File "/home/gaoi/.virtualenvs/mytaste/lib/python3.6/site-packages/rest_framework/views.py", line 505, in dispatch
    response = self.handle_exception(exc)
  File "/home/gaoi/.virtualenvs/mytaste/lib/python3.6/site-packages/rest_framework/views.py", line 465, in handle_exception
    self.raise_uncaught_exception(exc)
  File "/home/gaoi/.virtualenvs/mytaste/lib/python3.6/site-packages/rest_framework/views.py", line 476, in raise_uncaught_exception
    raise exc
  File "/home/gaoi/.virtualenvs/mytaste/lib/python3.6/site-packages/rest_framework/views.py", line 502, in dispatch
    response = handler(request, *args, **kwargs)
  File "/home/gaoi/.virtualenvs/mytaste/lib/python3.6/site-packages/rest_framework/generics.py", line 199, in get
    return self.list(request, *args, **kwargs)
  File "/home/gaoi/.virtualenvs/mytaste/lib/python3.6/site-packages/rest_framework/mixins.py", line 38, in list
    queryset = self.filter_queryset(self.get_queryset())
  File "/home/gaoi/.virtualenvs/mytaste/lib/python3.6/site-packages/rest_framework/generics.py", line 150, in filter_queryset
    queryset = backend().filter_queryset(self.request, queryset, self)
  File "/home/gaoi/.virtualenvs/mytaste/lib/python3.6/site-packages/rest_framework/filters.py", line 122, in filter_queryset
    queryset = queryset.filter(reduce(operator.and_, conditions))
  File "/home/gaoi/.virtualenvs/mytaste/lib/python3.6/site-packages/django/db/models/query.py", line 904, in filter
    return self._filter_or_exclude(False, *args, **kwargs)
  File "/home/gaoi/.virtualenvs/mytaste/lib/python3.6/site-packages/django/db/models/query.py", line 917, in _filter_or_exclude
    "Cannot filter a query once a slice has been taken."
AssertionError: Cannot filter a query once a slice has been taken.
{levelname} {asctime} {module} {process:d} {thread:d} {message}
{levelname} {asctime} {module} {process:d} {thread:d} {message}
{levelname} {asctime} {module} {process:d} {thread:d} {message}
{levelname} {asctime} {module} {process:d} {thread:d} {message}
Traceback (most recent call last):
  File "/home/gaoi/.virtualenvs/mytaste/lib/python3.6/site-packages/django/core/handlers/exception.py", line 34, in inner
    response = get_response(request)
  File "/home/gaoi/.virtualenvs/mytaste/lib/python3.6/site-packages/django/utils/deprecation.py", line 93, in __call__
    response = self.process_request(request)
  File "/home/gaoi/.virtualenvs/mytaste/lib/python3.6/site-packages/django/middleware/common.py", line 54, in process_request
    path = self.get_full_path_with_slash(request)
  File "/home/gaoi/.virtualenvs/mytaste/lib/python3.6/site-packages/django/middleware/common.py", line 94, in get_full_path_with_slash
    'url': request.get_host() + new_path,
RuntimeError: You called this URL via POST, but the URL doesn't end in a slash and you have APPEND_SLASH set. Django can't redirect to the slash URL while maintaining POST data. Change your form to point to api.mytaste.com:8000/v1/local_scenes/ (note the trailing slash), or set APPEND_SLASH=False in your Django settings.
{levelname} {asctime} {module} {process:d} {thread:d} {message}
{levelname} {asctime} {module} {process:d} {thread:d} {message}
Traceback (most recent call last):
  File "/home/gaoi/.virtualenvs/mytaste/lib/python3.6/site-packages/django/core/handlers/exception.py", line 34, in inner
    response = get_response(request)
  File "/home/gaoi/.virtualenvs/mytaste/lib/python3.6/site-packages/django/core/handlers/base.py", line 115, in _get_response
    response = self.process_exception_by_middleware(e, request)
  File "/home/gaoi/.virtualenvs/mytaste/lib/python3.6/site-packages/django/core/handlers/base.py", line 113, in _get_response
    response = wrapped_callback(request, *callback_args, **callback_kwargs)
  File "/home/gaoi/.virtualenvs/mytaste/lib/python3.6/site-packages/django/views/decorators/csrf.py", line 54, in wrapped_view
    return view_func(*args, **kwargs)
  File "/home/gaoi/.virtualenvs/mytaste/lib/python3.6/site-packages/django/views/generic/base.py", line 71, in view
    return self.dispatch(request, *args, **kwargs)
  File "/home/gaoi/.virtualenvs/mytaste/lib/python3.6/site-packages/rest_framework/views.py", line 505, in dispatch
    response = self.handle_exception(exc)
  File "/home/gaoi/.virtualenvs/mytaste/lib/python3.6/site-packages/rest_framework/views.py", line 465, in handle_exception
    self.raise_uncaught_exception(exc)
  File "/home/gaoi/.virtualenvs/mytaste/lib/python3.6/site-packages/rest_framework/views.py", line 476, in raise_uncaught_exception
    raise exc
  File "/home/gaoi/.virtualenvs/mytaste/lib/python3.6/site-packages/rest_framework/views.py", line 502, in dispatch
    response = handler(request, *args, **kwargs)
  File "/home/gaoi/.virtualenvs/mytaste/lib/python3.6/site-packages/rest_framework/generics.py", line 199, in get
    return self.list(request, *args, **kwargs)
  File "/home/gaoi/.virtualenvs/mytaste/lib/python3.6/site-packages/rest_framework/mixins.py", line 38, in list
    queryset = self.filter_queryset(self.get_queryset())
  File "/home/gaoi/.virtualenvs/mytaste/lib/python3.6/site-packages/rest_framework/generics.py", line 150, in filter_queryset
    queryset = backend().filter_queryset(self.request, queryset, self)
  File "/home/gaoi/.virtualenvs/mytaste/lib/python3.6/site-packages/django_filters/rest_framework/backends.py", line 96, in filter_queryset
    return filterset.qs
  File "/home/gaoi/.virtualenvs/mytaste/lib/python3.6/site-packages/django_filters/filterset.py", line 237, in qs
    qs = self.filter_queryset(qs)
  File "/home/gaoi/.virtualenvs/mytaste/lib/python3.6/site-packages/django_filters/filterset.py", line 224, in filter_queryset
    queryset = self.filters[name].filter(queryset, value)
  File "/home/gaoi/.virtualenvs/mytaste/lib/python3.6/site-packages/django_filters/filters.py", line 170, in filter
    return super().filter(qs, value)
  File "/home/gaoi/.virtualenvs/mytaste/lib/python3.6/site-packages/django_filters/filters.py", line 149, in filter
    qs = self.get_method(qs)(**{lookup: value})
  File "/home/gaoi/.virtualenvs/mytaste/lib/python3.6/site-packages/django/db/models/query.py", line 904, in filter
    return self._filter_or_exclude(False, *args, **kwargs)
  File "/home/gaoi/.virtualenvs/mytaste/lib/python3.6/site-packages/django/db/models/query.py", line 917, in _filter_or_exclude
    "Cannot filter a query once a slice has been taken."
AssertionError: Cannot filter a query once a slice has been taken.
{levelname} {asctime} {module} {process:d} {thread:d} {message}
{levelname} {asctime} {module} {process:d} {thread:d} {message}
Traceback (most recent call last):
  File "/home/gaoi/.virtualenvs/mytaste/lib/python3.6/site-packages/django/core/handlers/exception.py", line 34, in inner
    response = get_response(request)
  File "/home/gaoi/.virtualenvs/mytaste/lib/python3.6/site-packages/django/core/handlers/base.py", line 115, in _get_response
    response = self.process_exception_by_middleware(e, request)
  File "/home/gaoi/.virtualenvs/mytaste/lib/python3.6/site-packages/django/core/handlers/base.py", line 113, in _get_response
    response = wrapped_callback(request, *callback_args, **callback_kwargs)
  File "/home/gaoi/.virtualenvs/mytaste/lib/python3.6/site-packages/django/views/decorators/csrf.py", line 54, in wrapped_view
    return view_func(*args, **kwargs)
  File "/home/gaoi/.virtualenvs/mytaste/lib/python3.6/site-packages/django/views/generic/base.py", line 71, in view
    return self.dispatch(request, *args, **kwargs)
  File "/home/gaoi/.virtualenvs/mytaste/lib/python3.6/site-packages/rest_framework/views.py", line 505, in dispatch
    response = self.handle_exception(exc)
  File "/home/gaoi/.virtualenvs/mytaste/lib/python3.6/site-packages/rest_framework/views.py", line 465, in handle_exception
    self.raise_uncaught_exception(exc)
  File "/home/gaoi/.virtualenvs/mytaste/lib/python3.6/site-packages/rest_framework/views.py", line 476, in raise_uncaught_exception
    raise exc
  File "/home/gaoi/.virtualenvs/mytaste/lib/python3.6/site-packages/rest_framework/views.py", line 502, in dispatch
    response = handler(request, *args, **kwargs)
  File "/home/gaoi/.virtualenvs/mytaste/lib/python3.6/site-packages/rest_framework/generics.py", line 199, in get
    return self.list(request, *args, **kwargs)
  File "/home/gaoi/.virtualenvs/mytaste/lib/python3.6/site-packages/rest_framework/mixins.py", line 38, in list
    queryset = self.filter_queryset(self.get_queryset())
  File "/home/gaoi/.virtualenvs/mytaste/lib/python3.6/site-packages/rest_framework/generics.py", line 150, in filter_queryset
    queryset = backend().filter_queryset(self.request, queryset, self)
  File "/home/gaoi/.virtualenvs/mytaste/lib/python3.6/site-packages/django_filters/rest_framework/backends.py", line 96, in filter_queryset
    return filterset.qs
  File "/home/gaoi/.virtualenvs/mytaste/lib/python3.6/site-packages/django_filters/filterset.py", line 237, in qs
    qs = self.filter_queryset(qs)
  File "/home/gaoi/.virtualenvs/mytaste/lib/python3.6/site-packages/django_filters/filterset.py", line 224, in filter_queryset
    queryset = self.filters[name].filter(queryset, value)
  File "/home/gaoi/.virtualenvs/mytaste/lib/python3.6/site-packages/django_filters/filters.py", line 170, in filter
    return super().filter(qs, value)
  File "/home/gaoi/.virtualenvs/mytaste/lib/python3.6/site-packages/django_filters/filters.py", line 149, in filter
    qs = self.get_method(qs)(**{lookup: value})
  File "/home/gaoi/.virtualenvs/mytaste/lib/python3.6/site-packages/django/db/models/query.py", line 904, in filter
    return self._filter_or_exclude(False, *args, **kwargs)
  File "/home/gaoi/.virtualenvs/mytaste/lib/python3.6/site-packages/django/db/models/query.py", line 917, in _filter_or_exclude
    "Cannot filter a query once a slice has been taken."
AssertionError: Cannot filter a query once a slice has been taken.
{levelname} {asctime} {module} {process:d} {thread:d} {message}
{levelname} {asctime} {module} {process:d} {thread:d} {message}
Traceback (most recent call last):
  File "/home/gaoi/.virtualenvs/mytaste/lib/python3.6/site-packages/django/core/handlers/exception.py", line 34, in inner
    response = get_response(request)
  File "/home/gaoi/.virtualenvs/mytaste/lib/python3.6/site-packages/django/core/handlers/base.py", line 115, in _get_response
    response = self.process_exception_by_middleware(e, request)
  File "/home/gaoi/.virtualenvs/mytaste/lib/python3.6/site-packages/django/core/handlers/base.py", line 113, in _get_response
    response = wrapped_callback(request, *callback_args, **callback_kwargs)
  File "/home/gaoi/.virtualenvs/mytaste/lib/python3.6/site-packages/django/views/decorators/csrf.py", line 54, in wrapped_view
    return view_func(*args, **kwargs)
  File "/home/gaoi/.virtualenvs/mytaste/lib/python3.6/site-packages/django/views/generic/base.py", line 71, in view
    return self.dispatch(request, *args, **kwargs)
  File "/home/gaoi/.virtualenvs/mytaste/lib/python3.6/site-packages/rest_framework/views.py", line 505, in dispatch
    response = self.handle_exception(exc)
  File "/home/gaoi/.virtualenvs/mytaste/lib/python3.6/site-packages/rest_framework/views.py", line 465, in handle_exception
    self.raise_uncaught_exception(exc)
  File "/home/gaoi/.virtualenvs/mytaste/lib/python3.6/site-packages/rest_framework/views.py", line 476, in raise_uncaught_exception
    raise exc
  File "/home/gaoi/.virtualenvs/mytaste/lib/python3.6/site-packages/rest_framework/views.py", line 502, in dispatch
    response = handler(request, *args, **kwargs)
  File "/home/gaoi/.virtualenvs/mytaste/lib/python3.6/site-packages/rest_framework/generics.py", line 199, in get
    return self.list(request, *args, **kwargs)
  File "/home/gaoi/.virtualenvs/mytaste/lib/python3.6/site-packages/rest_framework/mixins.py", line 38, in list
    queryset = self.filter_queryset(self.get_queryset())
  File "/home/gaoi/.virtualenvs/mytaste/lib/python3.6/site-packages/rest_framework/generics.py", line 150, in filter_queryset
    queryset = backend().filter_queryset(self.request, queryset, self)
  File "/home/gaoi/.virtualenvs/mytaste/lib/python3.6/site-packages/django_filters/rest_framework/backends.py", line 96, in filter_queryset
    return filterset.qs
  File "/home/gaoi/.virtualenvs/mytaste/lib/python3.6/site-packages/django_filters/filterset.py", line 237, in qs
    qs = self.filter_queryset(qs)
  File "/home/gaoi/.virtualenvs/mytaste/lib/python3.6/site-packages/django_filters/filterset.py", line 224, in filter_queryset
    queryset = self.filters[name].filter(queryset, value)
  File "/home/gaoi/.virtualenvs/mytaste/lib/python3.6/site-packages/django_filters/filters.py", line 170, in filter
    return super().filter(qs, value)
  File "/home/gaoi/.virtualenvs/mytaste/lib/python3.6/site-packages/django_filters/filters.py", line 149, in filter
    qs = self.get_method(qs)(**{lookup: value})
  File "/home/gaoi/.virtualenvs/mytaste/lib/python3.6/site-packages/django/db/models/query.py", line 904, in filter
    return self._filter_or_exclude(False, *args, **kwargs)
  File "/home/gaoi/.virtualenvs/mytaste/lib/python3.6/site-packages/django/db/models/query.py", line 917, in _filter_or_exclude
    "Cannot filter a query once a slice has been taken."
AssertionError: Cannot filter a query once a slice has been taken.
{levelname} {asctime} {module} {process:d} {thread:d} {message}
{levelname} {asctime} {module} {process:d} {thread:d} {message}
{levelname} {asctime} {module} {process:d} {thread:d} {message}
{levelname} {asctime} {module} {process:d} {thread:d} {message}
{levelname} {asctime} {module} {process:d} {thread:d} {message}
{levelname} {asctime} {module} {process:d} {thread:d} {message}
{levelname} {asctime} {module} {process:d} {thread:d} {message}
{levelname} {asctime} {module} {process:d} {thread:d} {message}
Traceback (most recent call last):
  File "/home/gaoi/.virtualenvs/mytaste/lib/python3.6/site-packages/django/core/handlers/exception.py", line 34, in inner
    response = get_response(request)
  File "/home/gaoi/.virtualenvs/mytaste/lib/python3.6/site-packages/django/core/handlers/base.py", line 115, in _get_response
    response = self.process_exception_by_middleware(e, request)
  File "/home/gaoi/.virtualenvs/mytaste/lib/python3.6/site-packages/django/core/handlers/base.py", line 113, in _get_response
    response = wrapped_callback(request, *callback_args, **callback_kwargs)
  File "/home/gaoi/.virtualenvs/mytaste/lib/python3.6/site-packages/django/views/decorators/csrf.py", line 54, in wrapped_view
    return view_func(*args, **kwargs)
  File "/home/gaoi/.virtualenvs/mytaste/lib/python3.6/site-packages/django/views/generic/base.py", line 71, in view
    return self.dispatch(request, *args, **kwargs)
  File "/home/gaoi/.virtualenvs/mytaste/lib/python3.6/site-packages/rest_framework/views.py", line 505, in dispatch
    response = self.handle_exception(exc)
  File "/home/gaoi/.virtualenvs/mytaste/lib/python3.6/site-packages/rest_framework/views.py", line 465, in handle_exception
    self.raise_uncaught_exception(exc)
  File "/home/gaoi/.virtualenvs/mytaste/lib/python3.6/site-packages/rest_framework/views.py", line 476, in raise_uncaught_exception
    raise exc
  File "/home/gaoi/.virtualenvs/mytaste/lib/python3.6/site-packages/rest_framework/views.py", line 502, in dispatch
    response = handler(request, *args, **kwargs)
  File "/home/gaoi/.virtualenvs/mytaste/lib/python3.6/site-packages/rest_framework/generics.py", line 199, in get
    return self.list(request, *args, **kwargs)
  File "/home/gaoi/.virtualenvs/mytaste/lib/python3.6/site-packages/rest_framework/mixins.py", line 38, in list
    queryset = self.filter_queryset(self.get_queryset())
  File "/home/gaoi/.virtualenvs/mytaste/lib/python3.6/site-packages/rest_framework/generics.py", line 150, in filter_queryset
    queryset = backend().filter_queryset(self.request, queryset, self)
  File "/home/gaoi/.virtualenvs/mytaste/lib/python3.6/site-packages/django_filters/rest_framework/backends.py", line 96, in filter_queryset
    return filterset.qs
  File "/home/gaoi/.virtualenvs/mytaste/lib/python3.6/site-packages/django_filters/filterset.py", line 237, in qs
    qs = self.filter_queryset(qs)
  File "/home/gaoi/.virtualenvs/mytaste/lib/python3.6/site-packages/django_filters/filterset.py", line 224, in filter_queryset
    queryset = self.filters[name].filter(queryset, value)
  File "/home/gaoi/.virtualenvs/mytaste/lib/python3.6/site-packages/django_filters/filters.py", line 170, in filter
    return super().filter(qs, value)
  File "/home/gaoi/.virtualenvs/mytaste/lib/python3.6/site-packages/django_filters/filters.py", line 149, in filter
    qs = self.get_method(qs)(**{lookup: value})
  File "/home/gaoi/.virtualenvs/mytaste/lib/python3.6/site-packages/django/db/models/query.py", line 904, in filter
    return self._filter_or_exclude(False, *args, **kwargs)
  File "/home/gaoi/.virtualenvs/mytaste/lib/python3.6/site-packages/django/db/models/query.py", line 917, in _filter_or_exclude
    "Cannot filter a query once a slice has been taken."
AssertionError: Cannot filter a query once a slice has been taken.
{levelname} {asctime} {module} {process:d} {thread:d} {message}
{levelname} {asctime} {module} {process:d} {thread:d} {message}
Traceback (most recent call last):
  File "/home/gaoi/.virtualenvs/mytaste/lib/python3.6/site-packages/django/core/handlers/exception.py", line 34, in inner
    response = get_response(request)
  File "/home/gaoi/.virtualenvs/mytaste/lib/python3.6/site-packages/django/core/handlers/base.py", line 115, in _get_response
    response = self.process_exception_by_middleware(e, request)
  File "/home/gaoi/.virtualenvs/mytaste/lib/python3.6/site-packages/django/core/handlers/base.py", line 113, in _get_response
    response = wrapped_callback(request, *callback_args, **callback_kwargs)
  File "/home/gaoi/.virtualenvs/mytaste/lib/python3.6/site-packages/django/views/decorators/csrf.py", line 54, in wrapped_view
    return view_func(*args, **kwargs)
  File "/home/gaoi/.virtualenvs/mytaste/lib/python3.6/site-packages/django/views/generic/base.py", line 71, in view
    return self.dispatch(request, *args, **kwargs)
  File "/home/gaoi/.virtualenvs/mytaste/lib/python3.6/site-packages/rest_framework/views.py", line 505, in dispatch
    response = self.handle_exception(exc)
  File "/home/gaoi/.virtualenvs/mytaste/lib/python3.6/site-packages/rest_framework/views.py", line 465, in handle_exception
    self.raise_uncaught_exception(exc)
  File "/home/gaoi/.virtualenvs/mytaste/lib/python3.6/site-packages/rest_framework/views.py", line 476, in raise_uncaught_exception
    raise exc
  File "/home/gaoi/.virtualenvs/mytaste/lib/python3.6/site-packages/rest_framework/views.py", line 502, in dispatch
    response = handler(request, *args, **kwargs)
  File "/home/gaoi/PycharmProjects/myTaste/mytasteapi/mytasteapi/apps/scene/views.py", line 18, in get
    city = request.query_params.dict().city
AttributeError: 'dict' object has no attribute 'city'
{levelname} {asctime} {module} {process:d} {thread:d} {message}
{levelname} {asctime} {module} {process:d} {thread:d} {message}
Traceback (most recent call last):
  File "/home/gaoi/.virtualenvs/mytaste/lib/python3.6/site-packages/django/core/handlers/exception.py", line 34, in inner
    response = get_response(request)
  File "/home/gaoi/.virtualenvs/mytaste/lib/python3.6/site-packages/django/core/handlers/base.py", line 115, in _get_response
    response = self.process_exception_by_middleware(e, request)
  File "/home/gaoi/.virtualenvs/mytaste/lib/python3.6/site-packages/django/core/handlers/base.py", line 113, in _get_response
    response = wrapped_callback(request, *callback_args, **callback_kwargs)
  File "/home/gaoi/.virtualenvs/mytaste/lib/python3.6/site-packages/django/views/decorators/csrf.py", line 54, in wrapped_view
    return view_func(*args, **kwargs)
  File "/home/gaoi/.virtualenvs/mytaste/lib/python3.6/site-packages/django/views/generic/base.py", line 71, in view
    return self.dispatch(request, *args, **kwargs)
  File "/home/gaoi/.virtualenvs/mytaste/lib/python3.6/site-packages/rest_framework/views.py", line 505, in dispatch
    response = self.handle_exception(exc)
  File "/home/gaoi/.virtualenvs/mytaste/lib/python3.6/site-packages/rest_framework/views.py", line 465, in handle_exception
    self.raise_uncaught_exception(exc)
  File "/home/gaoi/.virtualenvs/mytaste/lib/python3.6/site-packages/rest_framework/views.py", line 476, in raise_uncaught_exception
    raise exc
  File "/home/gaoi/.virtualenvs/mytaste/lib/python3.6/site-packages/rest_framework/views.py", line 502, in dispatch
    response = handler(request, *args, **kwargs)
  File "/home/gaoi/PycharmProjects/myTaste/mytasteapi/mytasteapi/apps/scene/views.py", line 18, in get
    city = request.query_params.dict().city
AttributeError: 'dict' object has no attribute 'city'
{levelname} {asctime} {module} {process:d} {thread:d} {message}
{levelname} {asctime} {module} {process:d} {thread:d} {message}
Traceback (most recent call last):
  File "/home/gaoi/.virtualenvs/mytaste/lib/python3.6/site-packages/django/core/handlers/exception.py", line 34, in inner
    response = get_response(request)
  File "/home/gaoi/.virtualenvs/mytaste/lib/python3.6/site-packages/django/core/handlers/base.py", line 115, in _get_response
    response = self.process_exception_by_middleware(e, request)
  File "/home/gaoi/.virtualenvs/mytaste/lib/python3.6/site-packages/django/core/handlers/base.py", line 113, in _get_response
    response = wrapped_callback(request, *callback_args, **callback_kwargs)
  File "/home/gaoi/.virtualenvs/mytaste/lib/python3.6/site-packages/django/views/decorators/csrf.py", line 54, in wrapped_view
    return view_func(*args, **kwargs)
  File "/home/gaoi/.virtualenvs/mytaste/lib/python3.6/site-packages/django/views/generic/base.py", line 71, in view
    return self.dispatch(request, *args, **kwargs)
  File "/home/gaoi/.virtualenvs/mytaste/lib/python3.6/site-packages/rest_framework/views.py", line 505, in dispatch
    response = self.handle_exception(exc)
  File "/home/gaoi/.virtualenvs/mytaste/lib/python3.6/site-packages/rest_framework/views.py", line 465, in handle_exception
    self.raise_uncaught_exception(exc)
  File "/home/gaoi/.virtualenvs/mytaste/lib/python3.6/site-packages/rest_framework/views.py", line 476, in raise_uncaught_exception
    raise exc
  File "/home/gaoi/.virtualenvs/mytaste/lib/python3.6/site-packages/rest_framework/views.py", line 502, in dispatch
    response = handler(request, *args, **kwargs)
  File "/home/gaoi/PycharmProjects/myTaste/mytasteapi/mytasteapi/apps/scene/views.py", line 22, in get
    book_queryset = Scene.objects.filter(city__name__contains=city).order_by(order)[:8]
  File "/home/gaoi/.virtualenvs/mytaste/lib/python3.6/site-packages/django/db/models/manager.py", line 82, in manager_method
    return getattr(self.get_queryset(), name)(*args, **kwargs)
  File "/home/gaoi/.virtualenvs/mytaste/lib/python3.6/site-packages/django/db/models/query.py", line 904, in filter
    return self._filter_or_exclude(False, *args, **kwargs)
  File "/home/gaoi/.virtualenvs/mytaste/lib/python3.6/site-packages/django/db/models/query.py", line 923, in _filter_or_exclude
    clone.query.add_q(Q(*args, **kwargs))
  File "/home/gaoi/.virtualenvs/mytaste/lib/python3.6/site-packages/django/db/models/sql/query.py", line 1350, in add_q
    clause, _ = self._add_q(q_object, self.used_aliases)
  File "/home/gaoi/.virtualenvs/mytaste/lib/python3.6/site-packages/django/db/models/sql/query.py", line 1381, in _add_q
    check_filterable=check_filterable,
  File "/home/gaoi/.virtualenvs/mytaste/lib/python3.6/site-packages/django/db/models/sql/query.py", line 1311, in build_filter
    condition = self.build_lookup(lookups, col, value)
  File "/home/gaoi/.virtualenvs/mytaste/lib/python3.6/site-packages/django/db/models/sql/query.py", line 1170, in build_lookup
    raise ValueError("Cannot use None as a query value")
ValueError: Cannot use None as a query value
{levelname} {asctime} {module} {process:d} {thread:d} {message}
{levelname} {asctime} {module} {process:d} {thread:d} {message}
Traceback (most recent call last):
  File "/home/gaoi/.virtualenvs/mytaste/lib/python3.6/site-packages/django/core/handlers/exception.py", line 34, in inner
    response = get_response(request)
  File "/home/gaoi/.virtualenvs/mytaste/lib/python3.6/site-packages/django/core/handlers/base.py", line 115, in _get_response
    response = self.process_exception_by_middleware(e, request)
  File "/home/gaoi/.virtualenvs/mytaste/lib/python3.6/site-packages/django/core/handlers/base.py", line 113, in _get_response
    response = wrapped_callback(request, *callback_args, **callback_kwargs)
  File "/home/gaoi/.virtualenvs/mytaste/lib/python3.6/site-packages/django/views/decorators/csrf.py", line 54, in wrapped_view
    return view_func(*args, **kwargs)
  File "/home/gaoi/.virtualenvs/mytaste/lib/python3.6/site-packages/django/views/generic/base.py", line 71, in view
    return self.dispatch(request, *args, **kwargs)
  File "/home/gaoi/.virtualenvs/mytaste/lib/python3.6/site-packages/rest_framework/views.py", line 505, in dispatch
    response = self.handle_exception(exc)
  File "/home/gaoi/.virtualenvs/mytaste/lib/python3.6/site-packages/rest_framework/views.py", line 465, in handle_exception
    self.raise_uncaught_exception(exc)
  File "/home/gaoi/.virtualenvs/mytaste/lib/python3.6/site-packages/rest_framework/views.py", line 476, in raise_uncaught_exception
    raise exc
  File "/home/gaoi/.virtualenvs/mytaste/lib/python3.6/site-packages/rest_framework/views.py", line 502, in dispatch
    response = handler(request, *args, **kwargs)
  File "/home/gaoi/PycharmProjects/myTaste/mytasteapi/mytasteapi/apps/scene/views.py", line 19, in get
    city = request.query_params.dict()['city']
KeyError: 'city'
{levelname} {asctime} {module} {process:d} {thread:d} {message}
{levelname} {asctime} {module} {process:d} {thread:d} {message}
Traceback (most recent call last):
  File "/home/gaoi/.virtualenvs/mytaste/lib/python3.6/site-packages/django/core/handlers/exception.py", line 34, in inner
    response = get_response(request)
  File "/home/gaoi/.virtualenvs/mytaste/lib/python3.6/site-packages/django/core/handlers/base.py", line 115, in _get_response
    response = self.process_exception_by_middleware(e, request)
  File "/home/gaoi/.virtualenvs/mytaste/lib/python3.6/site-packages/django/core/handlers/base.py", line 113, in _get_response
    response = wrapped_callback(request, *callback_args, **callback_kwargs)
  File "/home/gaoi/.virtualenvs/mytaste/lib/python3.6/site-packages/django/views/decorators/csrf.py", line 54, in wrapped_view
    return view_func(*args, **kwargs)
  File "/home/gaoi/.virtualenvs/mytaste/lib/python3.6/site-packages/django/views/generic/base.py", line 71, in view
    return self.dispatch(request, *args, **kwargs)
  File "/home/gaoi/.virtualenvs/mytaste/lib/python3.6/site-packages/rest_framework/views.py", line 505, in dispatch
    response = self.handle_exception(exc)
  File "/home/gaoi/.virtualenvs/mytaste/lib/python3.6/site-packages/rest_framework/views.py", line 465, in handle_exception
    self.raise_uncaught_exception(exc)
  File "/home/gaoi/.virtualenvs/mytaste/lib/python3.6/site-packages/rest_framework/views.py", line 476, in raise_uncaught_exception
    raise exc
  File "/home/gaoi/.virtualenvs/mytaste/lib/python3.6/site-packages/rest_framework/views.py", line 502, in dispatch
    response = handler(request, *args, **kwargs)
  File "/home/gaoi/PycharmProjects/myTaste/mytasteapi/mytasteapi/apps/scene/views.py", line 19, in get
    print(request.query_params.dict()['city'])
KeyError: 'city'
{levelname} {asctime} {module} {process:d} {thread:d} {message}
{levelname} {asctime} {module} {process:d} {thread:d} {message}
Traceback (most recent call last):
  File "/home/gaoi/.virtualenvs/mytaste/lib/python3.6/site-packages/django/core/handlers/exception.py", line 34, in inner
    response = get_response(request)
  File "/home/gaoi/.virtualenvs/mytaste/lib/python3.6/site-packages/django/core/handlers/base.py", line 115, in _get_response
    response = self.process_exception_by_middleware(e, request)
  File "/home/gaoi/.virtualenvs/mytaste/lib/python3.6/site-packages/django/core/handlers/base.py", line 113, in _get_response
    response = wrapped_callback(request, *callback_args, **callback_kwargs)
  File "/home/gaoi/.virtualenvs/mytaste/lib/python3.6/site-packages/django/views/decorators/csrf.py", line 54, in wrapped_view
    return view_func(*args, **kwargs)
  File "/home/gaoi/.virtualenvs/mytaste/lib/python3.6/site-packages/django/views/generic/base.py", line 71, in view
    return self.dispatch(request, *args, **kwargs)
  File "/home/gaoi/.virtualenvs/mytaste/lib/python3.6/site-packages/rest_framework/views.py", line 505, in dispatch
    response = self.handle_exception(exc)
  File "/home/gaoi/.virtualenvs/mytaste/lib/python3.6/site-packages/rest_framework/views.py", line 465, in handle_exception
    self.raise_uncaught_exception(exc)
  File "/home/gaoi/.virtualenvs/mytaste/lib/python3.6/site-packages/rest_framework/views.py", line 476, in raise_uncaught_exception
    raise exc
  File "/home/gaoi/.virtualenvs/mytaste/lib/python3.6/site-packages/rest_framework/views.py", line 502, in dispatch
    response = handler(request, *args, **kwargs)
  File "/home/gaoi/PycharmProjects/myTaste/mytasteapi/mytasteapi/apps/scene/views.py", line 20, in get
    print(request.query_params.dict()['city'])
KeyError: 'city'
{levelname} {asctime} {module} {process:d} {thread:d} {message}
{levelname} {asctime} {module} {process:d} {thread:d} {message}
Traceback (most recent call last):
  File "/home/gaoi/.virtualenvs/mytaste/lib/python3.6/site-packages/django/core/handlers/exception.py", line 34, in inner
    response = get_response(request)
  File "/home/gaoi/.virtualenvs/mytaste/lib/python3.6/site-packages/django/core/handlers/base.py", line 115, in _get_response
    response = self.process_exception_by_middleware(e, request)
  File "/home/gaoi/.virtualenvs/mytaste/lib/python3.6/site-packages/django/core/handlers/base.py", line 113, in _get_response
    response = wrapped_callback(request, *callback_args, **callback_kwargs)
  File "/home/gaoi/.virtualenvs/mytaste/lib/python3.6/site-packages/django/views/decorators/csrf.py", line 54, in wrapped_view
    return view_func(*args, **kwargs)
  File "/home/gaoi/.virtualenvs/mytaste/lib/python3.6/site-packages/django/views/generic/base.py", line 71, in view
    return self.dispatch(request, *args, **kwargs)
  File "/home/gaoi/.virtualenvs/mytaste/lib/python3.6/site-packages/rest_framework/views.py", line 505, in dispatch
    response = self.handle_exception(exc)
  File "/home/gaoi/.virtualenvs/mytaste/lib/python3.6/site-packages/rest_framework/views.py", line 465, in handle_exception
    self.raise_uncaught_exception(exc)
  File "/home/gaoi/.virtualenvs/mytaste/lib/python3.6/site-packages/rest_framework/views.py", line 476, in raise_uncaught_exception
    raise exc
  File "/home/gaoi/.virtualenvs/mytaste/lib/python3.6/site-packages/rest_framework/views.py", line 502, in dispatch
    response = handler(request, *args, **kwargs)
  File "/home/gaoi/PycharmProjects/myTaste/mytasteapi/mytasteapi/apps/scene/views.py", line 20, in get
    print(request.query_params.dict()['city'])
KeyError: 'city'
{levelname} {asctime} {module} {process:d} {thread:d} {message}
{levelname} {asctime} {module} {process:d} {thread:d} {message}
Traceback (most recent call last):
  File "/home/gaoi/.virtualenvs/mytaste/lib/python3.6/site-packages/django/core/handlers/exception.py", line 34, in inner
    response = get_response(request)
  File "/home/gaoi/.virtualenvs/mytaste/lib/python3.6/site-packages/django/core/handlers/base.py", line 115, in _get_response
    response = self.process_exception_by_middleware(e, request)
  File "/home/gaoi/.virtualenvs/mytaste/lib/python3.6/site-packages/django/core/handlers/base.py", line 113, in _get_response
    response = wrapped_callback(request, *callback_args, **callback_kwargs)
  File "/home/gaoi/.virtualenvs/mytaste/lib/python3.6/site-packages/django/views/decorators/csrf.py", line 54, in wrapped_view
    return view_func(*args, **kwargs)
  File "/home/gaoi/.virtualenvs/mytaste/lib/python3.6/site-packages/django/views/generic/base.py", line 71, in view
    return self.dispatch(request, *args, **kwargs)
  File "/home/gaoi/.virtualenvs/mytaste/lib/python3.6/site-packages/rest_framework/views.py", line 505, in dispatch
    response = self.handle_exception(exc)
  File "/home/gaoi/.virtualenvs/mytaste/lib/python3.6/site-packages/rest_framework/views.py", line 465, in handle_exception
    self.raise_uncaught_exception(exc)
  File "/home/gaoi/.virtualenvs/mytaste/lib/python3.6/site-packages/rest_framework/views.py", line 476, in raise_uncaught_exception
    raise exc
  File "/home/gaoi/.virtualenvs/mytaste/lib/python3.6/site-packages/rest_framework/views.py", line 502, in dispatch
    response = handler(request, *args, **kwargs)
  File "/home/gaoi/PycharmProjects/myTaste/mytasteapi/mytasteapi/apps/scene/views.py", line 20, in get
    print(request.query_params.dict()['city'])
KeyError: 'city'
{levelname} {asctime} {module} {process:d} {thread:d} {message}
{levelname} {asctime} {module} {process:d} {thread:d} {message}
Traceback (most recent call last):
  File "/home/gaoi/.virtualenvs/mytaste/lib/python3.6/site-packages/django/core/handlers/exception.py", line 34, in inner
    response = get_response(request)
  File "/home/gaoi/.virtualenvs/mytaste/lib/python3.6/site-packages/django/core/handlers/base.py", line 115, in _get_response
    response = self.process_exception_by_middleware(e, request)
  File "/home/gaoi/.virtualenvs/mytaste/lib/python3.6/site-packages/django/core/handlers/base.py", line 113, in _get_response
    response = wrapped_callback(request, *callback_args, **callback_kwargs)
  File "/home/gaoi/.virtualenvs/mytaste/lib/python3.6/site-packages/django/views/decorators/csrf.py", line 54, in wrapped_view
    return view_func(*args, **kwargs)
  File "/home/gaoi/.virtualenvs/mytaste/lib/python3.6/site-packages/django/views/generic/base.py", line 71, in view
    return self.dispatch(request, *args, **kwargs)
  File "/home/gaoi/.virtualenvs/mytaste/lib/python3.6/site-packages/rest_framework/views.py", line 505, in dispatch
    response = self.handle_exception(exc)
  File "/home/gaoi/.virtualenvs/mytaste/lib/python3.6/site-packages/rest_framework/views.py", line 465, in handle_exception
    self.raise_uncaught_exception(exc)
  File "/home/gaoi/.virtualenvs/mytaste/lib/python3.6/site-packages/rest_framework/views.py", line 476, in raise_uncaught_exception
    raise exc
  File "/home/gaoi/.virtualenvs/mytaste/lib/python3.6/site-packages/rest_framework/views.py", line 502, in dispatch
    response = handler(request, *args, **kwargs)
  File "/home/gaoi/PycharmProjects/myTaste/mytasteapi/mytasteapi/apps/scene/views.py", line 28, in get
    obj.main_photo = "http://api.mytaste.com/" + main_photo
TypeError: must be str, not ImageFieldFile
{levelname} {asctime} {module} {process:d} {thread:d} {message}
{levelname} {asctime} {module} {process:d} {thread:d} {message}
{levelname} {asctime} {module} {process:d} {thread:d} {message}
{levelname} {asctime} {module} {process:d} {thread:d} {message}
{levelname} {asctime} {module} {process:d} {thread:d} {message}
{levelname} {asctime} {module} {process:d} {thread:d} {message}
{levelname} {asctime} {module} {process:d} {thread:d} {message}
{levelname} {asctime} {module} {process:d} {thread:d} {message}
{levelname} {asctime} {module} {process:d} {thread:d} {message}
{levelname} {asctime} {module} {process:d} {thread:d} {message}
{levelname} {asctime} {module} {process:d} {thread:d} {message}
{levelname} {asctime} {module} {process:d} {thread:d} {message}
{levelname} {asctime} {module} {process:d} {thread:d} {message}
{levelname} {asctime} {module} {process:d} {thread:d} {message}
{levelname} {asctime} {module} {process:d} {thread:d} {message}
{levelname} {asctime} {module} {process:d} {thread:d} {message}
{levelname} {asctime} {module} {process:d} {thread:d} {message}
{levelname} {asctime} {module} {process:d} {thread:d} {message}
{levelname} {asctime} {module} {process:d} {thread:d} {message}
{levelname} {asctime} {module} {process:d} {thread:d} {message}
{levelname} {asctime} {module} {process:d} {thread:d} {message}
{levelname} {asctime} {module} {process:d} {thread:d} {message}
{levelname} {asctime} {module} {process:d} {thread:d} {message}
{levelname} {asctime} {module} {process:d} {thread:d} {message}
{levelname} {asctime} {module} {process:d} {thread:d} {message}
{levelname} {asctime} {module} {process:d} {thread:d} {message}
{levelname} {asctime} {module} {process:d} {thread:d} {message}
{levelname} {asctime} {module} {process:d} {thread:d} {message}
{levelname} {asctime} {module} {process:d} {thread:d} {message}
{levelname} {asctime} {module} {process:d} {thread:d} {message}
{levelname} {asctime} {module} {process:d} {thread:d} {message}
{levelname} {asctime} {module} {process:d} {thread:d} {message}
{levelname} {asctime} {module} {process:d} {thread:d} {message}
{levelname} {asctime} {module} {process:d} {thread:d} {message}
{levelname} {asctime} {module} {process:d} {thread:d} {message}
{levelname} {asctime} {module} {process:d} {thread:d} {message}
{levelname} {asctime} {module} {process:d} {thread:d} {message}
{levelname} {asctime} {module} {process:d} {thread:d} {message}
{levelname} {asctime} {module} {process:d} {thread:d} {message}
{levelname} {asctime} {module} {process:d} {thread:d} {message}
{levelname} {asctime} {module} {process:d} {thread:d} {message}
{levelname} {asctime} {module} {process:d} {thread:d} {message}
{levelname} {asctime} {module} {process:d} {thread:d} {message}
{levelname} {asctime} {module} {process:d} {thread:d} {message}
{levelname} {asctime} {module} {process:d} {thread:d} {message}
{levelname} {asctime} {module} {process:d} {thread:d} {message}
{levelname} {asctime} {module} {process:d} {thread:d} {message}
{levelname} {asctime} {module} {process:d} {thread:d} {message}
{levelname} {asctime} {module} {process:d} {thread:d} {message}
{levelname} {asctime} {module} {process:d} {thread:d} {message}
{levelname} {asctime} {module} {process:d} {thread:d} {message}
{levelname} {asctime} {module} {process:d} {thread:d} {message}
{levelname} {asctime} {module} {process:d} {thread:d} {message}
{levelname} {asctime} {module} {process:d} {thread:d} {message}
{levelname} {asctime} {module} {process:d} {thread:d} {message}
{levelname} {asctime} {module} {process:d} {thread:d} {message}
{levelname} {asctime} {module} {process:d} {thread:d} {message}
{levelname} {asctime} {module} {process:d} {thread:d} {message}
{levelname} {asctime} {module} {process:d} {thread:d} {message}
{levelname} {asctime} {module} {process:d} {thread:d} {message}
{levelname} {asctime} {module} {process:d} {thread:d} {message}
{levelname} {asctime} {module} {process:d} {thread:d} {message}
Traceback (most recent call last):
  File "/home/gaoi/.virtualenvs/mytaste/lib/python3.6/site-packages/django/core/handlers/exception.py", line 34, in inner
    response = get_response(request)
  File "/home/gaoi/.virtualenvs/mytaste/lib/python3.6/site-packages/django/core/handlers/base.py", line 115, in _get_response
    response = self.process_exception_by_middleware(e, request)
  File "/home/gaoi/.virtualenvs/mytaste/lib/python3.6/site-packages/django/core/handlers/base.py", line 113, in _get_response
    response = wrapped_callback(request, *callback_args, **callback_kwargs)
  File "/home/gaoi/.virtualenvs/mytaste/lib/python3.6/site-packages/django/views/decorators/csrf.py", line 54, in wrapped_view
    return view_func(*args, **kwargs)
  File "/home/gaoi/.virtualenvs/mytaste/lib/python3.6/site-packages/django/views/generic/base.py", line 71, in view
    return self.dispatch(request, *args, **kwargs)
  File "/home/gaoi/.virtualenvs/mytaste/lib/python3.6/site-packages/rest_framework/views.py", line 505, in dispatch
    response = self.handle_exception(exc)
  File "/home/gaoi/.virtualenvs/mytaste/lib/python3.6/site-packages/rest_framework/views.py", line 465, in handle_exception
    self.raise_uncaught_exception(exc)
  File "/home/gaoi/.virtualenvs/mytaste/lib/python3.6/site-packages/rest_framework/views.py", line 476, in raise_uncaught_exception
    raise exc
  File "/home/gaoi/.virtualenvs/mytaste/lib/python3.6/site-packages/rest_framework/views.py", line 502, in dispatch
    response = handler(request, *args, **kwargs)
  File "/home/gaoi/PycharmProjects/myTaste/mytasteapi/mytasteapi/apps/scene/views.py", line 26, in get
    city__name__contains=city).order_by(order)[:8]
  File "/home/gaoi/.virtualenvs/mytaste/lib/python3.6/site-packages/django/db/models/query.py", line 1089, in order_by
    obj.query.add_ordering(*field_names)
  File "/home/gaoi/.virtualenvs/mytaste/lib/python3.6/site-packages/django/db/models/sql/query.py", line 1909, in add_ordering
    raise FieldError('Invalid order_by arguments: %s' % errors)
django.core.exceptions.FieldError: Invalid order_by arguments: ['']
{levelname} {asctime} {module} {process:d} {thread:d} {message}
{levelname} {asctime} {module} {process:d} {thread:d} {message}
Traceback (most recent call last):
  File "/home/gaoi/.virtualenvs/mytaste/lib/python3.6/site-packages/django/core/handlers/exception.py", line 34, in inner
    response = get_response(request)
  File "/home/gaoi/.virtualenvs/mytaste/lib/python3.6/site-packages/django/core/handlers/base.py", line 115, in _get_response
    response = self.process_exception_by_middleware(e, request)
  File "/home/gaoi/.virtualenvs/mytaste/lib/python3.6/site-packages/django/core/handlers/base.py", line 113, in _get_response
    response = wrapped_callback(request, *callback_args, **callback_kwargs)
  File "/home/gaoi/.virtualenvs/mytaste/lib/python3.6/site-packages/django/views/decorators/csrf.py", line 54, in wrapped_view
    return view_func(*args, **kwargs)
  File "/home/gaoi/.virtualenvs/mytaste/lib/python3.6/site-packages/django/views/generic/base.py", line 71, in view
    return self.dispatch(request, *args, **kwargs)
  File "/home/gaoi/.virtualenvs/mytaste/lib/python3.6/site-packages/rest_framework/views.py", line 488, in dispatch
    request = self.initialize_request(request, *args, **kwargs)
  File "/home/gaoi/.virtualenvs/mytaste/lib/python3.6/site-packages/rest_framework/views.py", line 389, in initialize_request
    parsers=self.get_parsers(),
  File "/home/gaoi/.virtualenvs/mytaste/lib/python3.6/site-packages/rest_framework/views.py", line 266, in get_parsers
    return [parser() for parser in self.parser_classes]
TypeError: 'type' object is not iterable
{levelname} {asctime} {module} {process:d} {thread:d} {message}
{levelname} {asctime} {module} {process:d} {thread:d} {message}
{levelname} {asctime} {module} {process:d} {thread:d} {message}
{levelname} {asctime} {module} {process:d} {thread:d} {message}
Traceback (most recent call last):
  File "/home/gaoi/.virtualenvs/mytaste/lib/python3.6/site-packages/django/core/handlers/exception.py", line 34, in inner
    response = get_response(request)
  File "/home/gaoi/.virtualenvs/mytaste/lib/python3.6/site-packages/django/core/handlers/base.py", line 115, in _get_response
    response = self.process_exception_by_middleware(e, request)
  File "/home/gaoi/.virtualenvs/mytaste/lib/python3.6/site-packages/django/core/handlers/base.py", line 113, in _get_response
    response = wrapped_callback(request, *callback_args, **callback_kwargs)
  File "/home/gaoi/.virtualenvs/mytaste/lib/python3.6/site-packages/django/views/decorators/csrf.py", line 54, in wrapped_view
    return view_func(*args, **kwargs)
  File "/home/gaoi/.virtualenvs/mytaste/lib/python3.6/site-packages/django/views/generic/base.py", line 71, in view
    return self.dispatch(request, *args, **kwargs)
  File "/home/gaoi/.virtualenvs/mytaste/lib/python3.6/site-packages/rest_framework/views.py", line 505, in dispatch
    response = self.handle_exception(exc)
  File "/home/gaoi/.virtualenvs/mytaste/lib/python3.6/site-packages/rest_framework/views.py", line 465, in handle_exception
    self.raise_uncaught_exception(exc)
  File "/home/gaoi/.virtualenvs/mytaste/lib/python3.6/site-packages/rest_framework/views.py", line 476, in raise_uncaught_exception
    raise exc
  File "/home/gaoi/.virtualenvs/mytaste/lib/python3.6/site-packages/rest_framework/views.py", line 502, in dispatch
    response = handler(request, *args, **kwargs)
  File "/home/gaoi/PycharmProjects/myTaste/mytasteapi/mytasteapi/apps/scene/views.py", line 37, in get
    page_scenes = page.paginate_queryset(queryset=scenes_queryset)
TypeError: paginate_queryset() missing 1 required positional argument: 'request'
{levelname} {asctime} {module} {process:d} {thread:d} {message}
